Workbook

Sheet Parametri
A1: Diffusore lineare – lanci e velocità da CFD (L = 500 / 1000 / 1500 mm)
A2: Getto verticale verso il basso, isotermia, fessura 40 mm
A3: Parametro | B3: Valore | C3: Unità | D3: Note
A4: Larghezza fessura h | B4: 0.04 | C4: m | D4: Input
A5: Altezza di installazione H | B5: 10 | C5: m | D5: Distanza diffusore-pavimento del modello CFD
A6: Spessore zona di influenza del pavimento | B6: 1.5 | C6: m | D6: Stima 1,5-2 m
A7: x massimo valido (getto libero) | B7: =B5-B6 -> 8.5 | C7: m | D7: H − spessore zona di influenza: oltre i dati CFD sono influenzati dal pavimento
A8: Quota zona occupata (dal pavimento) | B8: 1.8 | C8: m | D8: Input
A9: Distanza diffusore-zona occupata | B9: =B5-B8 -> 8.2 | C9: m | D9: H − quota zona occupata
A10: Velocità terminale vₜ | B10: 0.25 | C10: m/s | D10: Velocità a cui si calcola il lancio
A11: x minimo per cercare l'attraversamento | B11: 0.3 | C11: m | D11: Ignora nocciolo e primo calo vicino al diffusore
A12: x di riferimento 1 per k | B12: 5 | C12: m | D12: k = vₓ·x/Q letto a questa distanza
A13: x di riferimento 2 per k | B13: 7.6 | C13: m | D13: idem
A15: Parametri per lunghezza
A16: Lunghezza L [mm] | B16: L [m] | C16: Area geometrica [m²] | D16: Soglia vₜ/v₀ | E16: x min fit k [m] | F16: Note
A17: 500 | B17: =A17/1000 -> 0.5 | C17: =B17*$B$4 -> 0.02 | D17: 0.125 | E17: 4 | F17: Tratto 1/x sviluppato (≈4-8,5 m)
A18: 1000 | B18: =A18/1000 -> 1 | C18: =B18*$B$4 -> 0.04 | D18: 0.15 | E18: 4.9 | F18: Tratto 1/x sviluppato (≈5-8,5 m)
A19: 1500 | B19: =A19/1000 -> 1.5 | C19: =B19*$B$4 -> 0.06 | D19: 0.155 | E19: 7 | F19: Tratto 1/x NON sviluppato: k è apparente (x 7-8,5 m)
A22: Come si usa
A23: 1. Fogli CFD_L500 / CFD_L1000 / CFD_L1500: per ogni portata (fino a 5 blocchi) scrivi Q e incolla x [m] e velocità [m/s] nelle colonne blu (x=0 all'uscita, fino a 100 righe). I dati forniti sono già inseriti.
A24: 2. Riepilogo: area efficace, k, lancio a vₜ da CFD e velocità in zona occupata per ogni lunghezza e portata, con esito di validità.
A25: 3. Curve: curva normalizzata vₓ/v₀(x) per ogni lunghezza (mediata sulle portate) su griglia x = 0,5…9,5 m.
A26: 4. Catalogo: scegli lunghezza, portata e distanza; ottieni velocità, lancio a vₜ e la tabella vₓ(x) per le portate volute, usando la curva normalizzata CFD (non la legge k·Q/x).
A27: 5. Celle blu su fondo giallo = input; nere = formule; verdi = collegamenti ad altri fogli.
A28: 6. Catalogo_L_libera: come Catalogo ma per una L qualsiasi (curva e area efficace interpolate tra 500/1000/1500). Lancio_vs_L: tabella del lancio per un elenco di lunghezze alla Q scelta.
A29: 7. Catalogo_L_h / Lancio_vs_L_h: come sopra ma anche con larghezza fessura h diversa da 40 mm (es. 20, 30, 60), per similarità del getto piano. Stima non validata da CFD.
A30: 8. Lancio ORIZZONTALE (parete a 6 m): H_Parametri, H_CFD_L500/L1000/L1500 (dati da incollare), H_Curve, H_Catalogo (L e Q qualsiasi) e H_Lancio_vs_L. Interpola sui dati CFD in Q e in L.

Sheet Catalogo
A1: Catalogo: velocità e lancio da curva normalizzata CFD
A2: vₓ(x) = f_L(x)·v₀, v₀ = Q/(3600·A_eff) – nessuna legge k·Q/x: valido anche dove il getto non è sviluppato
A4: Lunghezza diffusore [mm] | B4: 500
A5: Portata Q [m³/h] | B5: 150
A6: Velocità terminale vₜ [m/s] | B6: =Parametri!B10 -> 0.25
A7: Indice lunghezza | B7: =MATCH(B4,Parametri!A17:A19,0) -> 1
A8: Area efficace [m²] | B8: =INDEX(Riepilogo!B5:B7,B7) -> 0.010136623
A9: Soglia vₜ/v₀ | B9: =INDEX(Riepilogo!F5:F7,B7) -> 0.125
A10: Campo Q simulato [m³/h] | B10: =INDEX(Riepilogo!H5:H7,B7)&" – "&INDEX(Riepilogo!I5:I7,B7) -> 80 – 250
A11: Distanza zona occupata [m] | B11: 8.22
A13: Risultato per Q = B5
A14: v₀ efficace [m/s] | B14: =B21 -> 4.1105076
A15: Lancio L a vₜ [m] | B15: =D21 -> 8.2270888
A16: vₓ in zona occupata [m/s] | B16: =E21 -> 0.25031676
A17: Esito | B17: =F21 -> OK
A19: Q [m³/h] | B19: v₀ eff. [m/s] | C19: vₜ/v₀ | D19: L a vₜ [m] | E19: vₓ zona occ. [m/s] | F19: Esito | G19: 0.5 | H19: 1 | I19: 1.5 | J19: 2 | K19: 2.5 | L19: 3 | M19: 3.5 | N19: 4 | O19: 4.5 | P19: 5 | Q19: 5.5 | R19: 6 | S19: 6.5 | T19: 7 | U19: 7.5 | V19: 8 | W19: 8.5 | X19: 9 | Y19: 9.5 | Z19: j* | AA19: x₁ | AB19: x₂ | AC19: v₁ | AD19: v₂ | AE19: idx occ
A20: f(x) curva L scelta → | G20: =INDEX(Curve!$G$1:$G$100,4+($B$7-1)*24+1+G$19*2) -> 0.22774569 | H20: =INDEX(Curve!$G$1:$G$100,4+($B$7-1)*24+1+H$19*2) -> 0.21285162 | I20: =INDEX(Curve!$G$1:$G$100,4+($B$7-1)*24+1+I$19*2) -> 0.19245601 | J20: =INDEX(Curve!$G$1:$G$100,4+($B$7-1)*24+1+J$19*2) -> 0.17728609 | K20: =INDEX(Curve!$G$1:$G$100,4+($B$7-1)*24+1+K$19*2) -> 0.16422859 | L20: =INDEX(Curve!$G$1:$G$100,4+($B$7-1)*24+1+L$19*2) -> 0.14863648 | M20: =INDEX(Curve!$G$1:$G$100,4+($B$7-1)*24+1+M$19*2) -> 0.13425179 | N20: =INDEX(Curve!$G$1:$G$100,4+($B$7-1)*24+1+N$19*2) -> 0.12272626 | ... Y20: =INDEX(Curve!$G$1:$G$100,4+($B$7-1)*24+1+Y$19*2) -> 0.033130897
A21: =B5 -> 150 | B21: =IF(OR(A21="",NOT(ISNUMBER($B$8))),"",A21/3600/$B$8) -> 4.1105076 | C21: =IF(B21="","",$B$6/B21) -> 0.06081974 | D21: =IF(B21="","",IF(AA21="",IF(ISNUMBER(G21),IF(G21<$B$6,"< 0,5","n.d."),"n.d."),EXP(LN(AA21)+(LN($B$6)-LN(AC21))*(LN(AB21)-LN(AA21))/(LN(AD21)-LN(AC21))))) -> 8.2270888 | E21: =IF(OR(B21="",AE21=""),"",IFERROR(EXP(LN(INDEX(G21:Y21,AE21))+(LN($B$11)-LN(INDEX(G$19:Y$19,AE21)))*(LN(INDEX(G21:Y21,AE21+1))-LN(INDEX(G21:Y21,AE21)))/(LN(INDEX(G$19:Y$19,AE21+1))-LN(INDEX(G$19:Y$19,AE21)))),"")) -> 0.25031676 | F21: =IF(B21="","",IF(OR(A21<VALUE(LEFT($B$10,FIND(" ",$B$10)-1))*0.99,A21>VALUE(MID($B$10,FIND("–",$B$10)+2,10))*1.01),"Q fuori dal campo simulato (estrapolazione)",IF(NOT(ISNUMBER(D21)),"vₜ non raggiunta / < 0,5 m",IF(C21>$B$9,"vₜ nel plateau/transizione: L poco significativo",IF(D21>Parametri!$B$7,"Oltre x max: troncato dal pavimento","OK"))))) -> OK | G21: =IF(OR($B21="",NOT(ISNUMBER(G$20))),"",G$20*$B21) -> 0.93615039 | H21: =IF(OR($B21="",NOT(ISNUMBER(H$20))),"",H$20*$B21) -> 0.8749282 | I21: =IF(OR($B21="",NOT(ISNUMBER(I$20))),"",I$20*$B21) -> 0.7910919 | J21: =IF(OR($B21="",NOT(ISNUMBER(J$20))),"",J$20*$B21) -> 0.72873582 | K21: =IF(OR($B21="",NOT(ISNUMBER(K$20))),"",K$20*$B21) -> 0.67506288 | L21: =IF(OR($B21="",NOT(ISNUMBER(L$20))),"",L$20*$B21) -> 0.6109714 | M21: =IF(OR($B21="",NOT(ISNUMBER(M$20))),"",M$20*$B21) -> 0.55184299 | N21: =IF(OR($B21="",NOT(ISNUMBER(N$20))),"",N$20*$B21) -> 0.50446721 | ... Y21: =IF(OR($B21="",NOT(ISNUMBER(Y$20))),"",Y$20*$B21) -> 0.13618481 | Z21: {=IF(B21="","",SUMPRODUCT(MAX(ISNUMBER(G21:X21)*ISNUMBER(H21:Y21)*(G21:X21>=$B$6)*(H21:Y21<$B$6)*(COLUMN(G21:X21)-COLUMN(G21)+1))))} -> 16 | AA21: =IF(OR(Z21="",Z21=0),"",INDEX(G$19:Y$19,Z21)) -> 8 | AB21: =IF(AA21="","",INDEX(G$19:Y$19,Z21+1)) -> 8.5 | AC21: =IF(AA21="","",INDEX(G21:Y21,Z21)) -> 0.26049333 | AD21: =IF(AA21="","",INDEX(G21:Y21,Z21+1)) -> 0.23829847 | AE21: =IF(B21="","",IFERROR(MATCH($B$11,$G$19:$Y$19,1),"")) -> 16
A22: 60 | B22: =IF(OR(A22="",NOT(ISNUMBER($B$8))),"",A22/3600/$B$8) -> 1.644203 | C22: =IF(B22="","",$B$6/B22) -> 0.15204935 | D22: =IF(B22="","",IF(AA22="",IF(ISNUMBER(G22),IF(G22<$B$6,"< 0,5","n.d."),"n.d."),EXP(LN(AA22)+(LN($B$6)-LN(AC22))*(LN(AB22)-LN(AA22))/(LN(AD22)-LN(AC22))))) -> 2.8780736 | E22: =IF(OR(B22="",AE22=""),"",IFERROR(EXP(LN(INDEX(G22:Y22,AE22))+(LN($B$11)-LN(INDEX(G$19:Y$19,AE22)))*(LN(INDEX(G22:Y22,AE22+1))-LN(INDEX(G22:Y22,AE22)))/(LN(INDEX(G$19:Y$19,AE22+1))-LN(INDEX(G$19:Y$19,AE22)))),"")) -> 0.1001267 | F22: =IF(B22="","",IF(OR(A22<VALUE(LEFT($B$10,FIND(" ",$B$10)-1))*0.99,A22>VALUE(MID($B$10,FIND("–",$B$10)+2,10))*1.01),"Q fuori dal campo simulato (estrapolazione)",IF(NOT(ISNUMBER(D22)),"vₜ non raggiunta / < 0,5 m",IF(C22>$B$9,"vₜ nel plateau/transizione: L poco significativo",IF(D22>Parametri!$B$7,"Oltre x max: troncato dal pavimento","OK"))))) -> Q fuori dal campo simulato (estrapolazione) | G22: =IF(OR($B22="",NOT(ISNUMBER(G$20))),"",G$20*$B22) -> 0.37446016 | H22: =IF(OR($B22="",NOT(ISNUMBER(H$20))),"",H$20*$B22) -> 0.34997128 | I22: =IF(OR($B22="",NOT(ISNUMBER(I$20))),"",I$20*$B22) -> 0.31643676 | J22: =IF(OR($B22="",NOT(ISNUMBER(J$20))),"",J$20*$B22) -> 0.29149433 | K22: =IF(OR($B22="",NOT(ISNUMBER(K$20))),"",K$20*$B22) -> 0.27002515 | L22: =IF(OR($B22="",NOT(ISNUMBER(L$20))),"",L$20*$B22) -> 0.24438856 | M22: =IF(OR($B22="",NOT(ISNUMBER(M$20))),"",M$20*$B22) -> 0.2207372 | N22: =IF(OR($B22="",NOT(ISNUMBER(N$20))),"",N$20*$B22) -> 0.20178689 | ... Y22: =IF(OR($B22="",NOT(ISNUMBER(Y$20))),"",Y$20*$B22) -> 0.054473922 | Z22: {=IF(B22="","",SUMPRODUCT(MAX(ISNUMBER(G22:X22)*ISNUMBER(H22:Y22)*(G22:X22>=$B$6)*(H22:Y22<$B$6)*(COLUMN(G22:X22)-COLUMN(G22)+1))))} -> 5 | AA22: =IF(OR(Z22="",Z22=0),"",INDEX(G$19:Y$19,Z22)) -> 2.5 | AB22: =IF(AA22="","",INDEX(G$19:Y$19,Z22+1)) -> 3 | AC22: =IF(AA22="","",INDEX(G22:Y22,Z22)) -> 0.27002515 | AD22: =IF(AA22="","",INDEX(G22:Y22,Z22+1)) -> 0.24438856 | AE22: =IF(B22="","",IFERROR(MATCH($B$11,$G$19:$Y$19,1),"")) -> 16
A23: 80 | B23: =IF(OR(A23="",NOT(ISNUMBER($B$8))),"",A23/3600/$B$8) -> 2.1922707 | C23: =IF(B23="","",$B$6/B23) -> 0.11403701 | D23: =IF(B23="","",IF(AA23="",IF(ISNUMBER(G23),IF(G23<$B$6,"< 0,5","n.d."),"n.d."),EXP(LN(AA23)+(LN($B$6)-LN(AC23))*(LN(AB23)-LN(AA23))/(LN(AD23)-LN(AC23))))) -> 4.3462678 | E23: =IF(OR(B23="",AE23=""),"",IFERROR(EXP(LN(INDEX(G23:Y23,AE23))+(LN($B$11)-LN(INDEX(G$19:Y$19,AE23)))*(LN(INDEX(G23:Y23,AE23+1))-LN(INDEX(G23:Y23,AE23)))/(LN(INDEX(G$19:Y$19,AE23+1))-LN(INDEX(G$19:Y$19,AE23)))),"")) -> 0.13350227 | F23: =IF(B23="","",IF(OR(A23<VALUE(LEFT($B$10,FIND(" ",$B$10)-1))*0.99,A23>VALUE(MID($B$10,FIND("–",$B$10)+2,10))*1.01),"Q fuori dal campo simulato (estrapolazione)",IF(NOT(ISNUMBER(D23)),"vₜ non raggiunta / < 0,5 m",IF(C23>$B$9,"vₜ nel plateau/transizione: L poco significativo",IF(D23>Parametri!$B$7,"Oltre x max: troncato dal pavimento","OK"))))) -> OK | G23: =IF(OR($B23="",NOT(ISNUMBER(G$20))),"",G$20*$B23) -> 0.49928021 | H23: =IF(OR($B23="",NOT(ISNUMBER(H$20))),"",H$20*$B23) -> 0.46662837 | I23: =IF(OR($B23="",NOT(ISNUMBER(I$20))),"",I$20*$B23) -> 0.42191568 | J23: =IF(OR($B23="",NOT(ISNUMBER(J$20))),"",J$20*$B23) -> 0.38865911 | K23: =IF(OR($B23="",NOT(ISNUMBER(K$20))),"",K$20*$B23) -> 0.36003354 | L23: =IF(OR($B23="",NOT(ISNUMBER(L$20))),"",L$20*$B23) -> 0.32585141 | M23: =IF(OR($B23="",NOT(ISNUMBER(M$20))),"",M$20*$B23) -> 0.29431626 | N23: =IF(OR($B23="",NOT(ISNUMBER(N$20))),"",N$20*$B23) -> 0.26904918 | ... Y23: =IF(OR($B23="",NOT(ISNUMBER(Y$20))),"",Y$20*$B23) -> 0.072631896 | Z23: {=IF(B23="","",SUMPRODUCT(MAX(ISNUMBER(G23:X23)*ISNUMBER(H23:Y23)*(G23:X23>=$B$6)*(H23:Y23<$B$6)*(COLUMN(G23:X23)-COLUMN(G23)+1))))} -> 8 | AA23: =IF(OR(Z23="",Z23=0),"",INDEX(G$19:Y$19,Z23)) -> 4 | AB23: =IF(AA23="","",INDEX(G$19:Y$19,Z23+1)) -> 4.5 | AC23: =IF(AA23="","",INDEX(G23:Y23,Z23)) -> 0.26904918 | AD23: =IF(AA23="","",INDEX(G23:Y23,Z23+1)) -> 0.24243074 | AE23: =IF(B23="","",IFERROR(MATCH($B$11,$G$19:$Y$19,1),"")) -> 16
A24: 100 | B24: =IF(OR(A24="",NOT(ISNUMBER($B$8))),"",A24/3600/$B$8) -> 2.7403384 | C24: =IF(B24="","",$B$6/B24) -> 0.091229609 | D24: =IF(B24="","",IF(AA24="",IF(ISNUMBER(G24),IF(G24<$B$6,"< 0,5","n.d."),"n.d."),EXP(LN(AA24)+(LN($B$6)-LN(AC24))*(LN(AB24)-LN(AA24))/(LN(AD24)-LN(AC24))))) -> 5.5318563 | E24: =IF(OR(B24="",AE24=""),"",IFERROR(EXP(LN(INDEX(G24:Y24,AE24))+(LN($B$11)-LN(INDEX(G$19:Y$19,AE24)))*(LN(INDEX(G24:Y24,AE24+1))-LN(INDEX(G24:Y24,AE24)))/(LN(INDEX(G$19:Y$19,AE24+1))-LN(INDEX(G$19:Y$19,AE24)))),"")) -> 0.16687784 | F24: =IF(B24="","",IF(OR(A24<VALUE(LEFT($B$10,FIND(" ",$B$10)-1))*0.99,A24>VALUE(MID($B$10,FIND("–",$B$10)+2,10))*1.01),"Q fuori dal campo simulato (estrapolazione)",IF(NOT(ISNUMBER(D24)),"vₜ non raggiunta / < 0,5 m",IF(C24>$B$9,"vₜ nel plateau/transizione: L poco significativo",IF(D24>Parametri!$B$7,"Oltre x max: troncato dal pavimento","OK"))))) -> OK | G24: =IF(OR($B24="",NOT(ISNUMBER(G$20))),"",G$20*$B24) -> 0.62410026 | H24: =IF(OR($B24="",NOT(ISNUMBER(H$20))),"",H$20*$B24) -> 0.58328546 | I24: =IF(OR($B24="",NOT(ISNUMBER(I$20))),"",I$20*$B24) -> 0.5273946 | J24: =IF(OR($B24="",NOT(ISNUMBER(J$20))),"",J$20*$B24) -> 0.48582388 | K24: =IF(OR($B24="",NOT(ISNUMBER(K$20))),"",K$20*$B24) -> 0.45004192 | L24: =IF(OR($B24="",NOT(ISNUMBER(L$20))),"",L$20*$B24) -> 0.40731426 | M24: =IF(OR($B24="",NOT(ISNUMBER(M$20))),"",M$20*$B24) -> 0.36789533 | N24: =IF(OR($B24="",NOT(ISNUMBER(N$20))),"",N$20*$B24) -> 0.33631148 | ... Y24: =IF(OR($B24="",NOT(ISNUMBER(Y$20))),"",Y$20*$B24) -> 0.09078987 | Z24: {=IF(B24="","",SUMPRODUCT(MAX(ISNUMBER(G24:X24)*ISNUMBER(H24:Y24)*(G24:X24>=$B$6)*(H24:Y24<$B$6)*(COLUMN(G24:X24)-COLUMN(G24)+1))))} -> 11 | AA24: =IF(OR(Z24="",Z24=0),"",INDEX(G$19:Y$19,Z24)) -> 5.5 | AB24: =IF(AA24="","",INDEX(G$19:Y$19,Z24+1)) -> 6 | AC24: =IF(AA24="","",INDEX(G24:Y24,Z24)) -> 0.2513947 | AD24: =IF(AA24="","",INDEX(G24:Y24,Z24+1)) -> 0.23118255 | AE24: =IF(B24="","",IFERROR(MATCH($B$11,$G$19:$Y$19,1),"")) -> 16
A25: 120 | B25: =IF(OR(A25="",NOT(ISNUMBER($B$8))),"",A25/3600/$B$8) -> 3.2884061 | C25: =IF(B25="","",$B$6/B25) -> 0.076024674 | D25: =IF(B25="","",IF(AA25="",IF(ISNUMBER(G25),IF(G25<$B$6,"< 0,5","n.d."),"n.d."),EXP(LN(AA25)+(LN($B$6)-LN(AC25))*(LN(AB25)-LN(AA25))/(LN(AD25)-LN(AC25))))) -> 6.6843254 | E25: =IF(OR(B25="",AE25=""),"",IFERROR(EXP(LN(INDEX(G25:Y25,AE25))+(LN($B$11)-LN(INDEX(G$19:Y$19,AE25)))*(LN(INDEX(G25:Y25,AE25+1))-LN(INDEX(G25:Y25,AE25)))/(LN(INDEX(G$19:Y$19,AE25+1))-LN(INDEX(G$19:Y$19,AE25)))),"")) -> 0.20025341 | F25: =IF(B25="","",IF(OR(A25<VALUE(LEFT($B$10,FIND(" ",$B$10)-1))*0.99,A25>VALUE(MID($B$10,FIND("–",$B$10)+2,10))*1.01),"Q fuori dal campo simulato (estrapolazione)",IF(NOT(ISNUMBER(D25)),"vₜ non raggiunta / < 0,5 m",IF(C25>$B$9,"vₜ nel plateau/transizione: L poco significativo",IF(D25>Parametri!$B$7,"Oltre x max: troncato dal pavimento","OK"))))) -> OK | G25: =IF(OR($B25="",NOT(ISNUMBER(G$20))),"",G$20*$B25) -> 0.74892031 | H25: =IF(OR($B25="",NOT(ISNUMBER(H$20))),"",H$20*$B25) -> 0.69994256 | I25: =IF(OR($B25="",NOT(ISNUMBER(I$20))),"",I$20*$B25) -> 0.63287352 | J25: =IF(OR($B25="",NOT(ISNUMBER(J$20))),"",J$20*$B25) -> 0.58298866 | K25: =IF(OR($B25="",NOT(ISNUMBER(K$20))),"",K$20*$B25) -> 0.5400503 | L25: =IF(OR($B25="",NOT(ISNUMBER(L$20))),"",L$20*$B25) -> 0.48877712 | M25: =IF(OR($B25="",NOT(ISNUMBER(M$20))),"",M$20*$B25) -> 0.44147439 | N25: =IF(OR($B25="",NOT(ISNUMBER(N$20))),"",N$20*$B25) -> 0.40357377 | ... Y25: =IF(OR($B25="",NOT(ISNUMBER(Y$20))),"",Y$20*$B25) -> 0.10894784 | Z25: {=IF(B25="","",SUMPRODUCT(MAX(ISNUMBER(G25:X25)*ISNUMBER(H25:Y25)*(G25:X25>=$B$6)*(H25:Y25<$B$6)*(COLUMN(G25:X25)-COLUMN(G25)+1))))} -> 13 | AA25: =IF(OR(Z25="",Z25=0),"",INDEX(G$19:Y$19,Z25)) -> 6.5 | AB25: =IF(AA25="","",INDEX(G$19:Y$19,Z25+1)) -> 7 | AC25: =IF(AA25="","",INDEX(G25:Y25,Z25)) -> 0.25682232 | AD25: =IF(AA25="","",INDEX(G25:Y25,Z25+1)) -> 0.23913578 | AE25: =IF(B25="","",IFERROR(MATCH($B$11,$G$19:$Y$19,1),"")) -> 16
A26: 150 | B26: =IF(OR(A26="",NOT(ISNUMBER($B$8))),"",A26/3600/$B$8) -> 4.1105076 | C26: =IF(B26="","",$B$6/B26) -> 0.06081974 | D26: =IF(B26="","",IF(AA26="",IF(ISNUMBER(G26),IF(G26<$B$6,"< 0,5","n.d."),"n.d."),EXP(LN(AA26)+(LN($B$6)-LN(AC26))*(LN(AB26)-LN(AA26))/(LN(AD26)-LN(AC26))))) -> 8.2270888 | E26: =IF(OR(B26="",AE26=""),"",IFERROR(EXP(LN(INDEX(G26:Y26,AE26))+(LN($B$11)-LN(INDEX(G$19:Y$19,AE26)))*(LN(INDEX(G26:Y26,AE26+1))-LN(INDEX(G26:Y26,AE26)))/(LN(INDEX(G$19:Y$19,AE26+1))-LN(INDEX(G$19:Y$19,AE26)))),"")) -> 0.25031676 | F26: =IF(B26="","",IF(OR(A26<VALUE(LEFT($B$10,FIND(" ",$B$10)-1))*0.99,A26>VALUE(MID($B$10,FIND("–",$B$10)+2,10))*1.01),"Q fuori dal campo simulato (estrapolazione)",IF(NOT(ISNUMBER(D26)),"vₜ non raggiunta / < 0,5 m",IF(C26>$B$9,"vₜ nel plateau/transizione: L poco significativo",IF(D26>Parametri!$B$7,"Oltre x max: troncato dal pavimento","OK"))))) -> OK | G26: =IF(OR($B26="",NOT(ISNUMBER(G$20))),"",G$20*$B26) -> 0.93615039 | H26: =IF(OR($B26="",NOT(ISNUMBER(H$20))),"",H$20*$B26) -> 0.8749282 | I26: =IF(OR($B26="",NOT(ISNUMBER(I$20))),"",I$20*$B26) -> 0.7910919 | J26: =IF(OR($B26="",NOT(ISNUMBER(J$20))),"",J$20*$B26) -> 0.72873582 | K26: =IF(OR($B26="",NOT(ISNUMBER(K$20))),"",K$20*$B26) -> 0.67506288 | L26: =IF(OR($B26="",NOT(ISNUMBER(L$20))),"",L$20*$B26) -> 0.6109714 | M26: =IF(OR($B26="",NOT(ISNUMBER(M$20))),"",M$20*$B26) -> 0.55184299 | N26: =IF(OR($B26="",NOT(ISNUMBER(N$20))),"",N$20*$B26) -> 0.50446721 | ... Y26: =IF(OR($B26="",NOT(ISNUMBER(Y$20))),"",Y$20*$B26) -> 0.13618481 | Z26: {=IF(B26="","",SUMPRODUCT(MAX(ISNUMBER(G26:X26)*ISNUMBER(H26:Y26)*(G26:X26>=$B$6)*(H26:Y26<$B$6)*(COLUMN(G26:X26)-COLUMN(G26)+1))))} -> 16 | AA26: =IF(OR(Z26="",Z26=0),"",INDEX(G$19:Y$19,Z26)) -> 8 | AB26: =IF(AA26="","",INDEX(G$19:Y$19,Z26+1)) -> 8.5 | AC26: =IF(AA26="","",INDEX(G26:Y26,Z26)) -> 0.26049333 | AD26: =IF(AA26="","",INDEX(G26:Y26,Z26+1)) -> 0.23829847 | AE26: =IF(B26="","",IFERROR(MATCH($B$11,$G$19:$Y$19,1),"")) -> 16
A27: 200 | B27: =IF(OR(A27="",NOT(ISNUMBER($B$8))),"",A27/3600/$B$8) -> 5.4806768 | C27: =IF(B27="","",$B$6/B27) -> 0.045614805 | D27: =IF(B27="","",IF(AA27="",IF(ISNUMBER(G27),IF(G27<$B$6,"< 0,5","n.d."),"n.d."),EXP(LN(AA27)+(LN($B$6)-LN(AC27))*(LN(AB27)-LN(AA27))/(LN(AD27)-LN(AC27))))) -> 9.1097888 | E27: =IF(OR(B27="",AE27=""),"",IFERROR(EXP(LN(INDEX(G27:Y27,AE27))+(LN($B$11)-LN(INDEX(G$19:Y$19,AE27)))*(LN(INDEX(G27:Y27,AE27+1))-LN(INDEX(G27:Y27,AE27)))/(LN(INDEX(G$19:Y$19,AE27+1))-LN(INDEX(G$19:Y$19,AE27)))),"")) -> 0.33375568 | F27: =IF(B27="","",IF(OR(A27<VALUE(LEFT($B$10,FIND(" ",$B$10)-1))*0.99,A27>VALUE(MID($B$10,FIND("–",$B$10)+2,10))*1.01),"Q fuori dal campo simulato (estrapolazione)",IF(NOT(ISNUMBER(D27)),"vₜ non raggiunta / < 0,5 m",IF(C27>$B$9,"vₜ nel plateau/transizione: L poco significativo",IF(D27>Parametri!$B$7,"Oltre x max: troncato dal pavimento","OK"))))) -> Oltre x max: troncato dal pavimento | G27: =IF(OR($B27="",NOT(ISNUMBER(G$20))),"",G$20*$B27) -> 1.2482005 | H27: =IF(OR($B27="",NOT(ISNUMBER(H$20))),"",H$20*$B27) -> 1.1665709 | I27: =IF(OR($B27="",NOT(ISNUMBER(I$20))),"",I$20*$B27) -> 1.0547892 | J27: =IF(OR($B27="",NOT(ISNUMBER(J$20))),"",J$20*$B27) -> 0.97164776 | K27: =IF(OR($B27="",NOT(ISNUMBER(K$20))),"",K$20*$B27) -> 0.90008384 | L27: =IF(OR($B27="",NOT(ISNUMBER(L$20))),"",L$20*$B27) -> 0.81462853 | M27: =IF(OR($B27="",NOT(ISNUMBER(M$20))),"",M$20*$B27) -> 0.73579065 | N27: =IF(OR($B27="",NOT(ISNUMBER(N$20))),"",N$20*$B27) -> 0.67262295 | ... Y27: =IF(OR($B27="",NOT(ISNUMBER(Y$20))),"",Y$20*$B27) -> 0.18157974 | Z27: {=IF(B27="","",SUMPRODUCT(MAX(ISNUMBER(G27:X27)*ISNUMBER(H27:Y27)*(G27:X27>=$B$6)*(H27:Y27<$B$6)*(COLUMN(G27:X27)-COLUMN(G27)+1))))} -> 18 | AA27: =IF(OR(Z27="",Z27=0),"",INDEX(G$19:Y$19,Z27)) -> 9 | AB27: =IF(AA27="","",INDEX(G$19:Y$19,Z27+1)) -> 9.5 | AC27: =IF(AA27="","",INDEX(G27:Y27,Z27)) -> 0.27421186 | AD27: =IF(AA27="","",INDEX(G27:Y27,Z27+1)) -> 0.18157974 | AE27: =IF(B27="","",IFERROR(MATCH($B$11,$G$19:$Y$19,1),"")) -> 16
A28: 250 | B28: =IF(OR(A28="",NOT(ISNUMBER($B$8))),"",A28/3600/$B$8) -> 6.850846 | C28: =IF(B28="","",$B$6/B28) -> 0.036491844 | D28: =IF(B28="","",IF(AA28="",IF(ISNUMBER(G28),IF(G28<$B$6,"< 0,5","n.d."),"n.d."),EXP(LN(AA28)+(LN($B$6)-LN(AC28))*(LN(AB28)-LN(AA28))/(LN(AD28)-LN(AC28))))) -> 9.3803611 | E28: =IF(OR(B28="",AE28=""),"",IFERROR(EXP(LN(INDEX(G28:Y28,AE28))+(LN($B$11)-LN(INDEX(G$19:Y$19,AE28)))*(LN(INDEX(G28:Y28,AE28+1))-LN(INDEX(G28:Y28,AE28)))/(LN(INDEX(G$19:Y$19,AE28+1))-LN(INDEX(G$19:Y$19,AE28)))),"")) -> 0.4171946 | F28: =IF(B28="","",IF(OR(A28<VALUE(LEFT($B$10,FIND(" ",$B$10)-1))*0.99,A28>VALUE(MID($B$10,FIND("–",$B$10)+2,10))*1.01),"Q fuori dal campo simulato (estrapolazione)",IF(NOT(ISNUMBER(D28)),"vₜ non raggiunta / < 0,5 m",IF(C28>$B$9,"vₜ nel plateau/transizione: L poco significativo",IF(D28>Parametri!$B$7,"Oltre x max: troncato dal pavimento","OK"))))) -> Oltre x max: troncato dal pavimento | G28: =IF(OR($B28="",NOT(ISNUMBER(G$20))),"",G$20*$B28) -> 1.5602506 | H28: =IF(OR($B28="",NOT(ISNUMBER(H$20))),"",H$20*$B28) -> 1.4582137 | I28: =IF(OR($B28="",NOT(ISNUMBER(I$20))),"",I$20*$B28) -> 1.3184865 | J28: =IF(OR($B28="",NOT(ISNUMBER(J$20))),"",J$20*$B28) -> 1.2145597 | K28: =IF(OR($B28="",NOT(ISNUMBER(K$20))),"",K$20*$B28) -> 1.1251048 | L28: =IF(OR($B28="",NOT(ISNUMBER(L$20))),"",L$20*$B28) -> 1.0182857 | M28: =IF(OR($B28="",NOT(ISNUMBER(M$20))),"",M$20*$B28) -> 0.91973831 | N28: =IF(OR($B28="",NOT(ISNUMBER(N$20))),"",N$20*$B28) -> 0.84077869 | ... Y28: =IF(OR($B28="",NOT(ISNUMBER(Y$20))),"",Y$20*$B28) -> 0.22697468 | Z28: {=IF(B28="","",SUMPRODUCT(MAX(ISNUMBER(G28:X28)*ISNUMBER(H28:Y28)*(G28:X28>=$B$6)*(H28:Y28<$B$6)*(COLUMN(G28:X28)-COLUMN(G28)+1))))} -> 18 | AA28: =IF(OR(Z28="",Z28=0),"",INDEX(G$19:Y$19,Z28)) -> 9 | AB28: =IF(AA28="","",INDEX(G$19:Y$19,Z28+1)) -> 9.5 | AC28: =IF(AA28="","",INDEX(G28:Y28,Z28)) -> 0.34276482 | AD28: =IF(AA28="","",INDEX(G28:Y28,Z28+1)) -> 0.22697468 | AE28: =IF(B28="","",IFERROR(MATCH($B$11,$G$19:$Y$19,1),"")) -> 16
A29: 300 | B29: =IF(OR(A29="",NOT(ISNUMBER($B$8))),"",A29/3600/$B$8) -> 8.2210151 | C29: =IF(B29="","",$B$6/B29) -> 0.03040987 | D29: =IF(B29="","",IF(AA29="",IF(ISNUMBER(G29),IF(G29<$B$6,"< 0,5","n.d."),"n.d."),EXP(LN(AA29)+(LN($B$6)-LN(AC29))*(LN(AB29)-LN(AA29))/(LN(AD29)-LN(AC29))))) -> n.d. | E29: =IF(OR(B29="",AE29=""),"",IFERROR(EXP(LN(INDEX(G29:Y29,AE29))+(LN($B$11)-LN(INDEX(G$19:Y$19,AE29)))*(LN(INDEX(G29:Y29,AE29+1))-LN(INDEX(G29:Y29,AE29)))/(LN(INDEX(G$19:Y$19,AE29+1))-LN(INDEX(G$19:Y$19,AE29)))),"")) -> 0.50063352 | F29: =IF(B29="","",IF(OR(A29<VALUE(LEFT($B$10,FIND(" ",$B$10)-1))*0.99,A29>VALUE(MID($B$10,FIND("–",$B$10)+2,10))*1.01),"Q fuori dal campo simulato (estrapolazione)",IF(NOT(ISNUMBER(D29)),"vₜ non raggiunta / < 0,5 m",IF(C29>$B$9,"vₜ nel plateau/transizione: L poco significativo",IF(D29>Parametri!$B$7,"Oltre x max: troncato dal pavimento","OK"))))) -> Q fuori dal campo simulato (estrapolazione) | G29: =IF(OR($B29="",NOT(ISNUMBER(G$20))),"",G$20*$B29) -> 1.8723008 | H29: =IF(OR($B29="",NOT(ISNUMBER(H$20))),"",H$20*$B29) -> 1.7498564 | I29: =IF(OR($B29="",NOT(ISNUMBER(I$20))),"",I$20*$B29) -> 1.5821838 | J29: =IF(OR($B29="",NOT(ISNUMBER(J$20))),"",J$20*$B29) -> 1.4574716 | K29: =IF(OR($B29="",NOT(ISNUMBER(K$20))),"",K$20*$B29) -> 1.3501258 | L29: =IF(OR($B29="",NOT(ISNUMBER(L$20))),"",L$20*$B29) -> 1.2219428 | M29: =IF(OR($B29="",NOT(ISNUMBER(M$20))),"",M$20*$B29) -> 1.103686 | N29: =IF(OR($B29="",NOT(ISNUMBER(N$20))),"",N$20*$B29) -> 1.0089344 | ... Y29: =IF(OR($B29="",NOT(ISNUMBER(Y$20))),"",Y$20*$B29) -> 0.27236961 | Z29: {=IF(B29="","",SUMPRODUCT(MAX(ISNUMBER(G29:X29)*ISNUMBER(H29:Y29)*(G29:X29>=$B$6)*(H29:Y29<$B$6)*(COLUMN(G29:X29)-COLUMN(G29)+1))))} -> 0 | AA29: =IF(OR(Z29="",Z29=0),"",INDEX(G$19:Y$19,Z29)) | AB29: =IF(AA29="","",INDEX(G$19:Y$19,Z29+1)) | AC29: =IF(AA29="","",INDEX(G29:Y29,Z29)) | AD29: =IF(AA29="","",INDEX(G29:Y29,Z29+1)) | AE29: =IF(B29="","",IFERROR(MATCH($B$11,$G$19:$Y$19,1),"")) -> 16
A31: Celle grigie in tabella = x oltre x max (influenza del pavimento). I valori di vₓ(x) sono letti dalla curva normalizzata della lunghezza scelta; la riga 21 usa Q della cella B5, le altre Q sono modificabili. | AA31: =ISNUMBER(V21) -> TRUE

Sheet Catalogo_L_libera
A1: Catalogo con lunghezza libera: velocità e lancio per qualsiasi L
A2: Curva vₓ/v₀(x), area efficace e soglia sono interpolate linearmente in L tra le due lunghezze CFD più vicine (500 / 1000 / 1500 mm). vₓ(x) = f_L(x)·v₀, v₀ = Q/(3600·A_eff)
A4: Lunghezza diffusore L [mm] | B4: 750
A5: Portata Q [m³/h] | B5: 150
A6: Velocità terminale vₜ [m/s] | B6: =Parametri!B10 -> 0.25
A7: Distanza zona occupata [m] | B7: =Catalogo!B11 -> 8.22
A9: Interpolazione sulla lunghezza
A10: Indice lunghezza inferiore | B10: =IFERROR(MIN(MATCH(B4,Parametri!$A$17:$A$19,1),2),1) -> 1
A11: Lunghezza CFD inferiore [mm] | B11: =INDEX(Parametri!$A$17:$A$19,B10) -> 500
A12: Lunghezza CFD superiore [mm] | B12: =INDEX(Parametri!$A$17:$A$19,B10+1) -> 1000
A13: Peso w (0 = inferiore, 1 = superiore) | B13: =(B4-B11)/(B12-B11) -> 0.5
A14: Area geometrica [m²] | B14: =B4/1000*Parametri!B4 -> 0.03
A15: Coeff. di contrazione interpolato | B15: =(1-B13)*INDEX(Riepilogo!$C$5:$C$7,B10)+B13*INDEX(Riepilogo!$C$5:$C$7,B10+1) -> 0.51921122
A16: Area efficace A_eff [m²] | B16: =B14*B15 -> 0.015576336
A17: Soglia vₜ/v₀ interpolata | B17: =(1-B13)*INDEX(Riepilogo!$F$5:$F$7,B10)+B13*INDEX(Riepilogo!$F$5:$F$7,B10+1) -> 0.1375
A18: Q minimo simulato [m³/h] | B18: =MAX(INDEX(Riepilogo!$H$5:$H$7,B10),INDEX(Riepilogo!$H$5:$H$7,B10+1)) -> 80
A19: Q massimo simulato [m³/h] | B19: =MIN(INDEX(Riepilogo!$I$5:$I$7,B10),INDEX(Riepilogo!$I$5:$I$7,B10+1)) -> 250
A20: Stato interpolazione | B20: =IF(OR(B4<MIN(Parametri!$A$17:$A$19),B4>MAX(Parametri!$A$17:$A$19)),"ESTRAPOLAZIONE: L fuori 500–1500 mm, non validato","Interpolazione tra L = "&B11&" e "&B12&" mm") -> Interpolazione tra L = 500 e 1000 mm
A22: Risultato per Q = B5
A23: v₀ efficace [m/s] | B23: =B30 -> 2.6749979
A24: Lancio L a vₜ [m] | B24: =D30 -> 6.7061637
A25: vₓ in zona occupata [m/s] | B25: =E30 -> 0.19933175
A26: Esito | B26: =F30 -> OK
A28: Q [m³/h] | B28: v₀ eff. [m/s] | C28: vₜ/v₀ | D28: L a vₜ [m] | E28: vₓ zona occ. [m/s] | F28: Esito | G28: 0.5 | H28: 1 | I28: 1.5 | J28: 2 | K28: 2.5 | L28: 3 | M28: 3.5 | N28: 4 | O28: 4.5 | P28: 5 | Q28: 5.5 | R28: 6 | S28: 6.5 | T28: 7 | U28: 7.5 | V28: 8 | W28: 8.5 | X28: 9 | Y28: 9.5 | Z28: j* | AA28: x₁ | AB28: x₂ | AC28: v₁ | AD28: v₂ | AE28: idx occ
A29: f(x) curva interpolata → | G29: =MAX(0.001,(1-$B$13)*INDEX(Curve!$G$1:$G$100,4+($B$10-1)*24+1+G$28*2)+$B$13*INDEX(Curve!$G$1:$G$100,4+$B$10*24+1+G$28*2)) -> 0.22367623 | H29: =MAX(0.001,(1-$B$13)*INDEX(Curve!$G$1:$G$100,4+($B$10-1)*24+1+H$28*2)+$B$13*INDEX(Curve!$G$1:$G$100,4+$B$10*24+1+H$28*2)) -> 0.21429958 | I29: =MAX(0.001,(1-$B$13)*INDEX(Curve!$G$1:$G$100,4+($B$10-1)*24+1+I$28*2)+$B$13*INDEX(Curve!$G$1:$G$100,4+$B$10*24+1+I$28*2)) -> 0.20437482 | J29: =MAX(0.001,(1-$B$13)*INDEX(Curve!$G$1:$G$100,4+($B$10-1)*24+1+J$28*2)+$B$13*INDEX(Curve!$G$1:$G$100,4+$B$10*24+1+J$28*2)) -> 0.19524183 | K29: =MAX(0.001,(1-$B$13)*INDEX(Curve!$G$1:$G$100,4+($B$10-1)*24+1+K$28*2)+$B$13*INDEX(Curve!$G$1:$G$100,4+$B$10*24+1+K$28*2)) -> 0.18528531 | L29: =MAX(0.001,(1-$B$13)*INDEX(Curve!$G$1:$G$100,4+($B$10-1)*24+1+L$28*2)+$B$13*INDEX(Curve!$G$1:$G$100,4+$B$10*24+1+L$28*2)) -> 0.17285666 | M29: =MAX(0.001,(1-$B$13)*INDEX(Curve!$G$1:$G$100,4+($B$10-1)*24+1+M$28*2)+$B$13*INDEX(Curve!$G$1:$G$100,4+$B$10*24+1+M$28*2)) -> 0.15890077 | N29: =MAX(0.001,(1-$B$13)*INDEX(Curve!$G$1:$G$100,4+($B$10-1)*24+1+N$28*2)+$B$13*INDEX(Curve!$G$1:$G$100,4+$B$10*24+1+N$28*2)) -> 0.14664571 | ... Y29: =MAX(0.001,(1-$B$13)*INDEX(Curve!$G$1:$G$100,4+($B$10-1)*24+1+Y$28*2)+$B$13*INDEX(Curve!$G$1:$G$100,4+$B$10*24+1+Y$28*2)) -> 0.039310978
A30: =B5 -> 150 | B30: =IF(OR(A30="",NOT(ISNUMBER($B$16))),"",A30/3600/$B$16) -> 2.6749979 | C30: =IF(B30="","",$B$6/B30) -> 0.093458019 | D30: =IF(B30="","",IF(AA30="",IF(ISNUMBER(G30),IF(G30<$B$6,"< 0,5","n.d."),"n.d."),EXP(LN(AA30)+(LN($B$6)-LN(AC30))*(LN(AB30)-LN(AA30))/(LN(AD30)-LN(AC30))))) -> 6.7061637 | E30: =IF(OR(B30="",AE30=""),"",IFERROR(EXP(LN(INDEX(G30:Y30,AE30))+(LN($B$7)-LN(INDEX(G$28:Y$28,AE30)))*(LN(INDEX(G30:Y30,AE30+1))-LN(INDEX(G30:Y30,AE30)))/(LN(INDEX(G$28:Y$28,AE30+1))-LN(INDEX(G$28:Y$28,AE30)))),"")) -> 0.19933175 | F30: =IF(B30="","",IF(OR($B$4<MIN(Parametri!$A$17:$A$19),$B$4>MAX(Parametri!$A$17:$A$19)),"L fuori 500–1500 mm: estrapolazione",IF(OR(A30<$B$18*0.99,A30>$B$19*1.01),"Q fuori dal campo simulato (estrapolazione)",IF(NOT(ISNUMBER(D30)),"vₜ non raggiunta / < 0,5 m",IF(C30>$B$17,"vₜ nel plateau/transizione: L poco significativo",IF(D30>Parametri!$B$7,"Oltre x max: troncato dal pavimento","OK")))))) -> OK | G30: =IF(OR($B30="",NOT(ISNUMBER(G$29))),"",G$29*$B30) -> 0.59833343 | H30: =IF(OR($B30="",NOT(ISNUMBER(H$29))),"",H$29*$B30) -> 0.57325092 | I30: =IF(OR($B30="",NOT(ISNUMBER(I$29))),"",I$29*$B30) -> 0.54670221 | J30: =IF(OR($B30="",NOT(ISNUMBER(J$29))),"",J$29*$B30) -> 0.52227147 | K30: =IF(OR($B30="",NOT(ISNUMBER(K$29))),"",K$29*$B30) -> 0.49563782 | L30: =IF(OR($B30="",NOT(ISNUMBER(L$29))),"",L$29*$B30) -> 0.46239121 | M30: =IF(OR($B30="",NOT(ISNUMBER(M$29))),"",M$29*$B30) -> 0.42505923 | N30: =IF(OR($B30="",NOT(ISNUMBER(N$29))),"",N$29*$B30) -> 0.39227696 | ... Y30: =IF(OR($B30="",NOT(ISNUMBER(Y$29))),"",Y$29*$B30) -> 0.10515678 | Z30: {=IF(B30="","",SUMPRODUCT(MAX(ISNUMBER(G30:X30)*ISNUMBER(H30:Y30)*(G30:X30>=$B$6)*(H30:Y30<$B$6)*(COLUMN(G30:X30)-COLUMN(G30)+1))))} -> 13 | AA30: =IF(OR(Z30="",Z30=0),"",INDEX(G$28:Y$28,Z30)) -> 6.5 | AB30: =IF(AA30="","",INDEX(G$28:Y$28,Z30+1)) -> 7 | AC30: =IF(AA30="","",INDEX(G30:Y30,Z30)) -> 0.25782445 | AD30: =IF(AA30="","",INDEX(G30:Y30,Z30+1)) -> 0.23963972 | AE30: =IF(B30="","",IFERROR(MATCH($B$7,$G$28:$Y$28,1),"")) -> 16
A31: 60 | B31: =IF(OR(A31="",NOT(ISNUMBER($B$16))),"",A31/3600/$B$16) -> 1.0699991 | C31: =IF(B31="","",$B$6/B31) -> 0.23364505 | D31: =IF(B31="","",IF(AA31="",IF(ISNUMBER(G31),IF(G31<$B$6,"< 0,5","n.d."),"n.d."),EXP(LN(AA31)+(LN($B$6)-LN(AC31))*(LN(AB31)-LN(AA31))/(LN(AD31)-LN(AC31))))) -> < 0,5 | E31: =IF(OR(B31="",AE31=""),"",IFERROR(EXP(LN(INDEX(G31:Y31,AE31))+(LN($B$7)-LN(INDEX(G$28:Y$28,AE31)))*(LN(INDEX(G31:Y31,AE31+1))-LN(INDEX(G31:Y31,AE31)))/(LN(INDEX(G$28:Y$28,AE31+1))-LN(INDEX(G$28:Y$28,AE31)))),"")) -> 0.079732699 | F31: =IF(B31="","",IF(OR($B$4<MIN(Parametri!$A$17:$A$19),$B$4>MAX(Parametri!$A$17:$A$19)),"L fuori 500–1500 mm: estrapolazione",IF(OR(A31<$B$18*0.99,A31>$B$19*1.01),"Q fuori dal campo simulato (estrapolazione)",IF(NOT(ISNUMBER(D31)),"vₜ non raggiunta / < 0,5 m",IF(C31>$B$17,"vₜ nel plateau/transizione: L poco significativo",IF(D31>Parametri!$B$7,"Oltre x max: troncato dal pavimento","OK")))))) -> Q fuori dal campo simulato (estrapolazione) | G31: =IF(OR($B31="",NOT(ISNUMBER(G$29))),"",G$29*$B31) -> 0.23933337 | H31: =IF(OR($B31="",NOT(ISNUMBER(H$29))),"",H$29*$B31) -> 0.22930037 | I31: =IF(OR($B31="",NOT(ISNUMBER(I$29))),"",I$29*$B31) -> 0.21868088 | J31: =IF(OR($B31="",NOT(ISNUMBER(J$29))),"",J$29*$B31) -> 0.20890859 | K31: =IF(OR($B31="",NOT(ISNUMBER(K$29))),"",K$29*$B31) -> 0.19825513 | L31: =IF(OR($B31="",NOT(ISNUMBER(L$29))),"",L$29*$B31) -> 0.18495648 | M31: =IF(OR($B31="",NOT(ISNUMBER(M$29))),"",M$29*$B31) -> 0.17002369 | N31: =IF(OR($B31="",NOT(ISNUMBER(N$29))),"",N$29*$B31) -> 0.15691078 | ... Y31: =IF(OR($B31="",NOT(ISNUMBER(Y$29))),"",Y$29*$B31) -> 0.042062713 | Z31: {=IF(B31="","",SUMPRODUCT(MAX(ISNUMBER(G31:X31)*ISNUMBER(H31:Y31)*(G31:X31>=$B$6)*(H31:Y31<$B$6)*(COLUMN(G31:X31)-COLUMN(G31)+1))))} -> 0 | AA31: =IF(OR(Z31="",Z31=0),"",INDEX(G$28:Y$28,Z31)) | AB31: =IF(AA31="","",INDEX(G$28:Y$28,Z31+1)) | AC31: =IF(AA31="","",INDEX(G31:Y31,Z31)) | AD31: =IF(AA31="","",INDEX(G31:Y31,Z31+1)) | AE31: =IF(B31="","",IFERROR(MATCH($B$7,$G$28:$Y$28,1),"")) -> 16
A32: 80 | B32: =IF(OR(A32="",NOT(ISNUMBER($B$16))),"",A32/3600/$B$16) -> 1.4266655 | C32: =IF(B32="","",$B$6/B32) -> 0.17523379 | D32: =IF(B32="","",IF(AA32="",IF(ISNUMBER(G32),IF(G32<$B$6,"< 0,5","n.d."),"n.d."),EXP(LN(AA32)+(LN($B$6)-LN(AC32))*(LN(AB32)-LN(AA32))/(LN(AD32)-LN(AC32))))) -> 2.894314 | E32: =IF(OR(B32="",AE32=""),"",IFERROR(EXP(LN(INDEX(G32:Y32,AE32))+(LN($B$7)-LN(INDEX(G$28:Y$28,AE32)))*(LN(INDEX(G32:Y32,AE32+1))-LN(INDEX(G32:Y32,AE32)))/(LN(INDEX(G$28:Y$28,AE32+1))-LN(INDEX(G$28:Y$28,AE32)))),"")) -> 0.10631027 | F32: =IF(B32="","",IF(OR($B$4<MIN(Parametri!$A$17:$A$19),$B$4>MAX(Parametri!$A$17:$A$19)),"L fuori 500–1500 mm: estrapolazione",IF(OR(A32<$B$18*0.99,A32>$B$19*1.01),"Q fuori dal campo simulato (estrapolazione)",IF(NOT(ISNUMBER(D32)),"vₜ non raggiunta / < 0,5 m",IF(C32>$B$17,"vₜ nel plateau/transizione: L poco significativo",IF(D32>Parametri!$B$7,"Oltre x max: troncato dal pavimento","OK")))))) -> vₜ nel plateau/transizione: L poco significativo | G32: =IF(OR($B32="",NOT(ISNUMBER(G$29))),"",G$29*$B32) -> 0.31911116 | H32: =IF(OR($B32="",NOT(ISNUMBER(H$29))),"",H$29*$B32) -> 0.30573382 | I32: =IF(OR($B32="",NOT(ISNUMBER(I$29))),"",I$29*$B32) -> 0.29157451 | J32: =IF(OR($B32="",NOT(ISNUMBER(J$29))),"",J$29*$B32) -> 0.27854478 | K32: =IF(OR($B32="",NOT(ISNUMBER(K$29))),"",K$29*$B32) -> 0.26434017 | L32: =IF(OR($B32="",NOT(ISNUMBER(L$29))),"",L$29*$B32) -> 0.24660864 | M32: =IF(OR($B32="",NOT(ISNUMBER(M$29))),"",M$29*$B32) -> 0.22669826 | N32: =IF(OR($B32="",NOT(ISNUMBER(N$29))),"",N$29*$B32) -> 0.20921438 | ... Y32: =IF(OR($B32="",NOT(ISNUMBER(Y$29))),"",Y$29*$B32) -> 0.056083617 | Z32: {=IF(B32="","",SUMPRODUCT(MAX(ISNUMBER(G32:X32)*ISNUMBER(H32:Y32)*(G32:X32>=$B$6)*(H32:Y32<$B$6)*(COLUMN(G32:X32)-COLUMN(G32)+1))))} -> 5 | AA32: =IF(OR(Z32="",Z32=0),"",INDEX(G$28:Y$28,Z32)) -> 2.5 | AB32: =IF(AA32="","",INDEX(G$28:Y$28,Z32+1)) -> 3 | AC32: =IF(AA32="","",INDEX(G32:Y32,Z32)) -> 0.26434017 | AD32: =IF(AA32="","",INDEX(G32:Y32,Z32+1)) -> 0.24660864 | AE32: =IF(B32="","",IFERROR(MATCH($B$7,$G$28:$Y$28,1),"")) -> 16
A33: 100 | B33: =IF(OR(A33="",NOT(ISNUMBER($B$16))),"",A33/3600/$B$16) -> 1.7833319 | C33: =IF(B33="","",$B$6/B33) -> 0.14018703 | D33: =IF(B33="","",IF(AA33="",IF(ISNUMBER(G33),IF(G33<$B$6,"< 0,5","n.d."),"n.d."),EXP(LN(AA33)+(LN($B$6)-LN(AC33))*(LN(AB33)-LN(AA33))/(LN(AD33)-LN(AC33))))) -> 4.2619638 | E33: =IF(OR(B33="",AE33=""),"",IFERROR(EXP(LN(INDEX(G33:Y33,AE33))+(LN($B$7)-LN(INDEX(G$28:Y$28,AE33)))*(LN(INDEX(G33:Y33,AE33+1))-LN(INDEX(G33:Y33,AE33)))/(LN(INDEX(G$28:Y$28,AE33+1))-LN(INDEX(G$28:Y$28,AE33)))),"")) -> 0.13288783 | F33: =IF(B33="","",IF(OR($B$4<MIN(Parametri!$A$17:$A$19),$B$4>MAX(Parametri!$A$17:$A$19)),"L fuori 500–1500 mm: estrapolazione",IF(OR(A33<$B$18*0.99,A33>$B$19*1.01),"Q fuori dal campo simulato (estrapolazione)",IF(NOT(ISNUMBER(D33)),"vₜ non raggiunta / < 0,5 m",IF(C33>$B$17,"vₜ nel plateau/transizione: L poco significativo",IF(D33>Parametri!$B$7,"Oltre x max: troncato dal pavimento","OK")))))) -> vₜ nel plateau/transizione: L poco significativo | G33: =IF(OR($B33="",NOT(ISNUMBER(G$29))),"",G$29*$B33) -> 0.39888895 | H33: =IF(OR($B33="",NOT(ISNUMBER(H$29))),"",H$29*$B33) -> 0.38216728 | I33: =IF(OR($B33="",NOT(ISNUMBER(I$29))),"",I$29*$B33) -> 0.36446814 | J33: =IF(OR($B33="",NOT(ISNUMBER(J$29))),"",J$29*$B33) -> 0.34818098 | K33: =IF(OR($B33="",NOT(ISNUMBER(K$29))),"",K$29*$B33) -> 0.33042521 | L33: =IF(OR($B33="",NOT(ISNUMBER(L$29))),"",L$29*$B33) -> 0.3082608 | M33: =IF(OR($B33="",NOT(ISNUMBER(M$29))),"",M$29*$B33) -> 0.28337282 | N33: =IF(OR($B33="",NOT(ISNUMBER(N$29))),"",N$29*$B33) -> 0.26151797 | ... Y33: =IF(OR($B33="",NOT(ISNUMBER(Y$29))),"",Y$29*$B33) -> 0.070104521 | Z33: {=IF(B33="","",SUMPRODUCT(MAX(ISNUMBER(G33:X33)*ISNUMBER(H33:Y33)*(G33:X33>=$B$6)*(H33:Y33<$B$6)*(COLUMN(G33:X33)-COLUMN(G33)+1))))} -> 8 | AA33: =IF(OR(Z33="",Z33=0),"",INDEX(G$28:Y$28,Z33)) -> 4 | AB33: =IF(AA33="","",INDEX(G$28:Y$28,Z33+1)) -> 4.5 | AC33: =IF(AA33="","",INDEX(G33:Y33,Z33)) -> 0.26151797 | AD33: =IF(AA33="","",INDEX(G33:Y33,Z33+1)) -> 0.24053652 | AE33: =IF(B33="","",IFERROR(MATCH($B$7,$G$28:$Y$28,1),"")) -> 16
A34: 120 | B34: =IF(OR(A34="",NOT(ISNUMBER($B$16))),"",A34/3600/$B$16) -> 2.1399983 | C34: =IF(B34="","",$B$6/B34) -> 0.11682252 | D34: =IF(B34="","",IF(AA34="",IF(ISNUMBER(G34),IF(G34<$B$6,"< 0,5","n.d."),"n.d."),EXP(LN(AA34)+(LN($B$6)-LN(AC34))*(LN(AB34)-LN(AA34))/(LN(AD34)-LN(AC34))))) -> 5.3166428 | E34: =IF(OR(B34="",AE34=""),"",IFERROR(EXP(LN(INDEX(G34:Y34,AE34))+(LN($B$7)-LN(INDEX(G$28:Y$28,AE34)))*(LN(INDEX(G34:Y34,AE34+1))-LN(INDEX(G34:Y34,AE34)))/(LN(INDEX(G$28:Y$28,AE34+1))-LN(INDEX(G$28:Y$28,AE34)))),"")) -> 0.1594654 | F34: =IF(B34="","",IF(OR($B$4<MIN(Parametri!$A$17:$A$19),$B$4>MAX(Parametri!$A$17:$A$19)),"L fuori 500–1500 mm: estrapolazione",IF(OR(A34<$B$18*0.99,A34>$B$19*1.01),"Q fuori dal campo simulato (estrapolazione)",IF(NOT(ISNUMBER(D34)),"vₜ non raggiunta / < 0,5 m",IF(C34>$B$17,"vₜ nel plateau/transizione: L poco significativo",IF(D34>Parametri!$B$7,"Oltre x max: troncato dal pavimento","OK")))))) -> OK | G34: =IF(OR($B34="",NOT(ISNUMBER(G$29))),"",G$29*$B34) -> 0.47866674 | H34: =IF(OR($B34="",NOT(ISNUMBER(H$29))),"",H$29*$B34) -> 0.45860074 | I34: =IF(OR($B34="",NOT(ISNUMBER(I$29))),"",I$29*$B34) -> 0.43736177 | J34: =IF(OR($B34="",NOT(ISNUMBER(J$29))),"",J$29*$B34) -> 0.41781718 | K34: =IF(OR($B34="",NOT(ISNUMBER(K$29))),"",K$29*$B34) -> 0.39651026 | L34: =IF(OR($B34="",NOT(ISNUMBER(L$29))),"",L$29*$B34) -> 0.36991297 | M34: =IF(OR($B34="",NOT(ISNUMBER(M$29))),"",M$29*$B34) -> 0.34004738 | N34: =IF(OR($B34="",NOT(ISNUMBER(N$29))),"",N$29*$B34) -> 0.31382157 | ... Y34: =IF(OR($B34="",NOT(ISNUMBER(Y$29))),"",Y$29*$B34) -> 0.084125425 | Z34: {=IF(B34="","",SUMPRODUCT(MAX(ISNUMBER(G34:X34)*ISNUMBER(H34:Y34)*(G34:X34>=$B$6)*(H34:Y34<$B$6)*(COLUMN(G34:X34)-COLUMN(G34)+1))))} -> 10 | AA34: =IF(OR(Z34="",Z34=0),"",INDEX(G$28:Y$28,Z34)) -> 5 | AB34: =IF(AA34="","",INDEX(G$28:Y$28,Z34+1)) -> 5.5 | AC34: =IF(AA34="","",INDEX(G34:Y34,Z34)) -> 0.26500663 | AD34: =IF(AA34="","",INDEX(G34:Y34,Z34+1)) -> 0.24208098 | AE34: =IF(B34="","",IFERROR(MATCH($B$7,$G$28:$Y$28,1),"")) -> 16
A35: 150 | B35: =IF(OR(A35="",NOT(ISNUMBER($B$16))),"",A35/3600/$B$16) -> 2.6749979 | C35: =IF(B35="","",$B$6/B35) -> 0.093458019 | D35: =IF(B35="","",IF(AA35="",IF(ISNUMBER(G35),IF(G35<$B$6,"< 0,5","n.d."),"n.d."),EXP(LN(AA35)+(LN($B$6)-LN(AC35))*(LN(AB35)-LN(AA35))/(LN(AD35)-LN(AC35))))) -> 6.7061637 | E35: =IF(OR(B35="",AE35=""),"",IFERROR(EXP(LN(INDEX(G35:Y35,AE35))+(LN($B$7)-LN(INDEX(G$28:Y$28,AE35)))*(LN(INDEX(G35:Y35,AE35+1))-LN(INDEX(G35:Y35,AE35)))/(LN(INDEX(G$28:Y$28,AE35+1))-LN(INDEX(G$28:Y$28,AE35)))),"")) -> 0.19933175 | F35: =IF(B35="","",IF(OR($B$4<MIN(Parametri!$A$17:$A$19),$B$4>MAX(Parametri!$A$17:$A$19)),"L fuori 500–1500 mm: estrapolazione",IF(OR(A35<$B$18*0.99,A35>$B$19*1.01),"Q fuori dal campo simulato (estrapolazione)",IF(NOT(ISNUMBER(D35)),"vₜ non raggiunta / < 0,5 m",IF(C35>$B$17,"vₜ nel plateau/transizione: L poco significativo",IF(D35>Parametri!$B$7,"Oltre x max: troncato dal pavimento","OK")))))) -> OK | G35: =IF(OR($B35="",NOT(ISNUMBER(G$29))),"",G$29*$B35) -> 0.59833343 | H35: =IF(OR($B35="",NOT(ISNUMBER(H$29))),"",H$29*$B35) -> 0.57325092 | I35: =IF(OR($B35="",NOT(ISNUMBER(I$29))),"",I$29*$B35) -> 0.54670221 | J35: =IF(OR($B35="",NOT(ISNUMBER(J$29))),"",J$29*$B35) -> 0.52227147 | K35: =IF(OR($B35="",NOT(ISNUMBER(K$29))),"",K$29*$B35) -> 0.49563782 | L35: =IF(OR($B35="",NOT(ISNUMBER(L$29))),"",L$29*$B35) -> 0.46239121 | M35: =IF(OR($B35="",NOT(ISNUMBER(M$29))),"",M$29*$B35) -> 0.42505923 | N35: =IF(OR($B35="",NOT(ISNUMBER(N$29))),"",N$29*$B35) -> 0.39227696 | ... Y35: =IF(OR($B35="",NOT(ISNUMBER(Y$29))),"",Y$29*$B35) -> 0.10515678 | Z35: {=IF(B35="","",SUMPRODUCT(MAX(ISNUMBER(G35:X35)*ISNUMBER(H35:Y35)*(G35:X35>=$B$6)*(H35:Y35<$B$6)*(COLUMN(G35:X35)-COLUMN(G35)+1))))} -> 13 | AA35: =IF(OR(Z35="",Z35=0),"",INDEX(G$28:Y$28,Z35)) -> 6.5 | AB35: =IF(AA35="","",INDEX(G$28:Y$28,Z35+1)) -> 7 | AC35: =IF(AA35="","",INDEX(G35:Y35,Z35)) -> 0.25782445 | AD35: =IF(AA35="","",INDEX(G35:Y35,Z35+1)) -> 0.23963972 | AE35: =IF(B35="","",IFERROR(MATCH($B$7,$G$28:$Y$28,1),"")) -> 16
A36: 200 | B36: =IF(OR(A36="",NOT(ISNUMBER($B$16))),"",A36/3600/$B$16) -> 3.5666638 | C36: =IF(B36="","",$B$6/B36) -> 0.070093514 | D36: =IF(B36="","",IF(AA36="",IF(ISNUMBER(G36),IF(G36<$B$6,"< 0,5","n.d."),"n.d."),EXP(LN(AA36)+(LN($B$6)-LN(AC36))*(LN(AB36)-LN(AA36))/(LN(AD36)-LN(AC36))))) -> 8.546623 | E36: =IF(OR(B36="",AE36=""),"",IFERROR(EXP(LN(INDEX(G36:Y36,AE36))+(LN($B$7)-LN(INDEX(G$28:Y$28,AE36)))*(LN(INDEX(G36:Y36,AE36+1))-LN(INDEX(G36:Y36,AE36)))/(LN(INDEX(G$28:Y$28,AE36+1))-LN(INDEX(G$28:Y$28,AE36)))),"")) -> 0.26577566 | F36: =IF(B36="","",IF(OR($B$4<MIN(Parametri!$A$17:$A$19),$B$4>MAX(Parametri!$A$17:$A$19)),"L fuori 500–1500 mm: estrapolazione",IF(OR(A36<$B$18*0.99,A36>$B$19*1.01),"Q fuori dal campo simulato (estrapolazione)",IF(NOT(ISNUMBER(D36)),"vₜ non raggiunta / < 0,5 m",IF(C36>$B$17,"vₜ nel plateau/transizione: L poco significativo",IF(D36>Parametri!$B$7,"Oltre x max: troncato dal pavimento","OK")))))) -> Oltre x max: troncato dal pavimento | G36: =IF(OR($B36="",NOT(ISNUMBER(G$29))),"",G$29*$B36) -> 0.7977779 | H36: =IF(OR($B36="",NOT(ISNUMBER(H$29))),"",H$29*$B36) -> 0.76433456 | I36: =IF(OR($B36="",NOT(ISNUMBER(I$29))),"",I$29*$B36) -> 0.72893628 | J36: =IF(OR($B36="",NOT(ISNUMBER(J$29))),"",J$29*$B36) -> 0.69636196 | K36: =IF(OR($B36="",NOT(ISNUMBER(K$29))),"",K$29*$B36) -> 0.66085043 | L36: =IF(OR($B36="",NOT(ISNUMBER(L$29))),"",L$29*$B36) -> 0.61652161 | M36: =IF(OR($B36="",NOT(ISNUMBER(M$29))),"",M$29*$B36) -> 0.56674564 | N36: =IF(OR($B36="",NOT(ISNUMBER(N$29))),"",N$29*$B36) -> 0.52303594 | ... Y36: =IF(OR($B36="",NOT(ISNUMBER(Y$29))),"",Y$29*$B36) -> 0.14020904 | Z36: {=IF(B36="","",SUMPRODUCT(MAX(ISNUMBER(G36:X36)*ISNUMBER(H36:Y36)*(G36:X36>=$B$6)*(H36:Y36<$B$6)*(COLUMN(G36:X36)-COLUMN(G36)+1))))} -> 17 | AA36: =IF(OR(Z36="",Z36=0),"",INDEX(G$28:Y$28,Z36)) -> 8.5 | AB36: =IF(AA36="","",INDEX(G$28:Y$28,Z36+1)) -> 9 | AC36: =IF(AA36="","",INDEX(G36:Y36,Z36)) -> 0.25367663 | AD36: =IF(AA36="","",INDEX(G36:Y36,Z36+1)) -> 0.21778456 | AE36: =IF(B36="","",IFERROR(MATCH($B$7,$G$28:$Y$28,1),"")) -> 16
A37: 250 | B37: =IF(OR(A37="",NOT(ISNUMBER($B$16))),"",A37/3600/$B$16) -> 4.4583298 | C37: =IF(B37="","",$B$6/B37) -> 0.056074811 | D37: =IF(B37="","",IF(AA37="",IF(ISNUMBER(G37),IF(G37<$B$6,"< 0,5","n.d."),"n.d."),EXP(LN(AA37)+(LN($B$6)-LN(AC37))*(LN(AB37)-LN(AA37))/(LN(AD37)-LN(AC37))))) -> 9.0946267 | E37: =IF(OR(B37="",AE37=""),"",IFERROR(EXP(LN(INDEX(G37:Y37,AE37))+(LN($B$7)-LN(INDEX(G$28:Y$28,AE37)))*(LN(INDEX(G37:Y37,AE37+1))-LN(INDEX(G37:Y37,AE37)))/(LN(INDEX(G$28:Y$28,AE37+1))-LN(INDEX(G$28:Y$28,AE37)))),"")) -> 0.33221958 | F37: =IF(B37="","",IF(OR($B$4<MIN(Parametri!$A$17:$A$19),$B$4>MAX(Parametri!$A$17:$A$19)),"L fuori 500–1500 mm: estrapolazione",IF(OR(A37<$B$18*0.99,A37>$B$19*1.01),"Q fuori dal campo simulato (estrapolazione)",IF(NOT(ISNUMBER(D37)),"vₜ non raggiunta / < 0,5 m",IF(C37>$B$17,"vₜ nel plateau/transizione: L poco significativo",IF(D37>Parametri!$B$7,"Oltre x max: troncato dal pavimento","OK")))))) -> Oltre x max: troncato dal pavimento | G37: =IF(OR($B37="",NOT(ISNUMBER(G$29))),"",G$29*$B37) -> 0.99722238 | H37: =IF(OR($B37="",NOT(ISNUMBER(H$29))),"",H$29*$B37) -> 0.9554182 | I37: =IF(OR($B37="",NOT(ISNUMBER(I$29))),"",I$29*$B37) -> 0.91117035 | J37: =IF(OR($B37="",NOT(ISNUMBER(J$29))),"",J$29*$B37) -> 0.87045245 | K37: =IF(OR($B37="",NOT(ISNUMBER(K$29))),"",K$29*$B37) -> 0.82606303 | L37: =IF(OR($B37="",NOT(ISNUMBER(L$29))),"",L$29*$B37) -> 0.77065201 | M37: =IF(OR($B37="",NOT(ISNUMBER(M$29))),"",M$29*$B37) -> 0.70843205 | N37: =IF(OR($B37="",NOT(ISNUMBER(N$29))),"",N$29*$B37) -> 0.65379493 | ... Y37: =IF(OR($B37="",NOT(ISNUMBER(Y$29))),"",Y$29*$B37) -> 0.1752613 | Z37: {=IF(B37="","",SUMPRODUCT(MAX(ISNUMBER(G37:X37)*ISNUMBER(H37:Y37)*(G37:X37>=$B$6)*(H37:Y37<$B$6)*(COLUMN(G37:X37)-COLUMN(G37)+1))))} -> 18 | AA37: =IF(OR(Z37="",Z37=0),"",INDEX(G$28:Y$28,Z37)) -> 9 | AB37: =IF(AA37="","",INDEX(G$28:Y$28,Z37+1)) -> 9.5 | AC37: =IF(AA37="","",INDEX(G37:Y37,Z37)) -> 0.2722307 | AD37: =IF(AA37="","",INDEX(G37:Y37,Z37+1)) -> 0.1752613 | AE37: =IF(B37="","",IFERROR(MATCH($B$7,$G$28:$Y$28,1),"")) -> 16
A38: 300 | B38: =IF(OR(A38="",NOT(ISNUMBER($B$16))),"",A38/3600/$B$16) -> 5.3499957 | C38: =IF(B38="","",$B$6/B38) -> 0.046729009 | D38: =IF(B38="","",IF(AA38="",IF(ISNUMBER(G38),IF(G38<$B$6,"< 0,5","n.d."),"n.d."),EXP(LN(AA38)+(LN($B$6)-LN(AC38))*(LN(AB38)-LN(AA38))/(LN(AD38)-LN(AC38))))) -> 9.3005034 | E38: =IF(OR(B38="",AE38=""),"",IFERROR(EXP(LN(INDEX(G38:Y38,AE38))+(LN($B$7)-LN(INDEX(G$28:Y$28,AE38)))*(LN(INDEX(G38:Y38,AE38+1))-LN(INDEX(G38:Y38,AE38)))/(LN(INDEX(G$28:Y$28,AE38+1))-LN(INDEX(G$28:Y$28,AE38)))),"")) -> 0.3986635 | F38: =IF(B38="","",IF(OR($B$4<MIN(Parametri!$A$17:$A$19),$B$4>MAX(Parametri!$A$17:$A$19)),"L fuori 500–1500 mm: estrapolazione",IF(OR(A38<$B$18*0.99,A38>$B$19*1.01),"Q fuori dal campo simulato (estrapolazione)",IF(NOT(ISNUMBER(D38)),"vₜ non raggiunta / < 0,5 m",IF(C38>$B$17,"vₜ nel plateau/transizione: L poco significativo",IF(D38>Parametri!$B$7,"Oltre x max: troncato dal pavimento","OK")))))) -> Q fuori dal campo simulato (estrapolazione) | G38: =IF(OR($B38="",NOT(ISNUMBER(G$29))),"",G$29*$B38) -> 1.1966669 | H38: =IF(OR($B38="",NOT(ISNUMBER(H$29))),"",H$29*$B38) -> 1.1465018 | I38: =IF(OR($B38="",NOT(ISNUMBER(I$29))),"",I$29*$B38) -> 1.0934044 | J38: =IF(OR($B38="",NOT(ISNUMBER(J$29))),"",J$29*$B38) -> 1.0445429 | K38: =IF(OR($B38="",NOT(ISNUMBER(K$29))),"",K$29*$B38) -> 0.99127564 | L38: =IF(OR($B38="",NOT(ISNUMBER(L$29))),"",L$29*$B38) -> 0.92478241 | M38: =IF(OR($B38="",NOT(ISNUMBER(M$29))),"",M$29*$B38) -> 0.85011846 | N38: =IF(OR($B38="",NOT(ISNUMBER(N$29))),"",N$29*$B38) -> 0.78455391 | ... Y38: =IF(OR($B38="",NOT(ISNUMBER(Y$29))),"",Y$29*$B38) -> 0.21031356 | Z38: {=IF(B38="","",SUMPRODUCT(MAX(ISNUMBER(G38:X38)*ISNUMBER(H38:Y38)*(G38:X38>=$B$6)*(H38:Y38<$B$6)*(COLUMN(G38:X38)-COLUMN(G38)+1))))} -> 18 | AA38: =IF(OR(Z38="",Z38=0),"",INDEX(G$28:Y$28,Z38)) -> 9 | AB38: =IF(AA38="","",INDEX(G$28:Y$28,Z38+1)) -> 9.5 | AC38: =IF(AA38="","",INDEX(G38:Y38,Z38)) -> 0.32667684 | AD38: =IF(AA38="","",INDEX(G38:Y38,Z38+1)) -> 0.21031356 | AE38: =IF(B38="","",IFERROR(MATCH($B$7,$G$28:$Y$28,1),"")) -> 16
A40: Celle grigie in tabella = x oltre x max (influenza del pavimento). La riga 30 usa la Q della cella B5; le altre Q sono modificabili. Fuori da 500–1500 mm la curva viene estrapolata linearmente: usare solo come stima orientativa.

Sheet Lancio_vs_L
A1: Lancio a vₜ in funzione della lunghezza L (portata fissata)
A2: Stesso metodo del foglio Catalogo_L_libera, su un elenco di lunghezze. Q, vₜ e distanza zona occupata arrivano da Catalogo_L_libera.
A4: Portata Q [m³/h] | B4: =Catalogo_L_libera!B5 -> 150
A5: Velocità terminale vₜ [m/s] | B5: =Catalogo_L_libera!B6 -> 0.25
A6: Distanza zona occupata [m] | B6: =Catalogo_L_libera!B7 -> 8.22
A8: L [mm] | B8: Idx inf. | C8: Peso w | D8: Coeff. contraz. | E8: A_eff [m²] | F8: v₀ eff. [m/s] | G8: vₜ/v₀ | H8: Soglia vₜ/v₀ | I8: Lancio a vₜ [m] | J8: vₓ zona occ. [m/s] | K8: Esito | L8: 0.5 | M8: 1 | N8: 1.5 | O8: 2 | P8: 2.5 | Q8: 3 | R8: 3.5 | S8: 4 | T8: 4.5 | U8: 5 | V8: 5.5 | W8: 6 | X8: 6.5 | Y8: 7 | Z8: 7.5 | AA8: 8 | AB8: 8.5 | AC8: 9 | AD8: 9.5 | AE8: j* | AF8: x₁ | AG8: x₂ | AH8: v₁ | AI8: v₂ | AJ8: idx occ
A9: 500 | B9: =IFERROR(MIN(MATCH(A9,Parametri!$A$17:$A$19,1),2),1) -> 1 | C9: =(A9-INDEX(Parametri!$A$17:$A$19,B9))/(INDEX(Parametri!$A$17:$A$19,B9+1)-INDEX(Parametri!$A$17:$A$19,B9)) -> 0 | D9: =(1-C9)*INDEX(Riepilogo!$C$5:$C$7,B9)+C9*INDEX(Riepilogo!$C$5:$C$7,B9+1) -> 0.50683116 | E9: =A9/1000*Parametri!$B$4*D9 -> 0.010136623 | F9: =$B$4/3600/E9 -> 4.1105076 | G9: =$B$5/F9 -> 0.06081974 | H9: =(1-C9)*INDEX(Riepilogo!$F$5:$F$7,B9)+C9*INDEX(Riepilogo!$F$5:$F$7,B9+1) -> 0.125 | I9: =IF(AF9="",IF(ISNUMBER(L9),IF(L9<$B$5,"< 0,5","n.d."),"n.d."),EXP(LN(AF9)+(LN($B$5)-LN(AH9))*(LN(AG9)-LN(AF9))/(LN(AI9)-LN(AH9)))) -> 8.2270888 | J9: =IF(AJ9="","",IFERROR(EXP(LN(INDEX(L9:AD9,AJ9))+(LN($B$6)-LN(INDEX(L$8:AD$8,AJ9)))*(LN(INDEX(L9:AD9,AJ9+1))-LN(INDEX(L9:AD9,AJ9)))/(LN(INDEX(L$8:AD$8,AJ9+1))-LN(INDEX(L$8:AD$8,AJ9)))),"")) -> 0.25031676 | K9: =IF(OR(A9<MIN(Parametri!$A$17:$A$19),A9>MAX(Parametri!$A$17:$A$19)),"L fuori 500–1500 mm: estrapolazione",IF(OR($B$4<MAX(INDEX(Riepilogo!$H$5:$H$7,B9),INDEX(Riepilogo!$H$5:$H$7,B9+1))*0.99,$B$4>MIN(INDEX(Riepilogo!$I$5:$I$7,B9),INDEX(Riepilogo!$I$5:$I$7,B9+1))*1.01),"Q fuori dal campo simulato (estrapolazione)",IF(NOT(ISNUMBER(I9)),"vₜ non raggiunta / < 0,5 m",IF(G9>H9,"vₜ nel plateau/transizione: L poco significativo",IF(I9>Parametri!$B$7,"Oltre x max: troncato dal pavimento","OK"))))) -> OK | L9: =$F9*MAX(0.001,(1-$C9)*INDEX(Curve!$G$1:$G$100,4+($B9-1)*24+1+L$8*2)+$C9*INDEX(Curve!$G$1:$G$100,4+$B9*24+1+L$8*2)) -> 0.93615039 | M9: =$F9*MAX(0.001,(1-$C9)*INDEX(Curve!$G$1:$G$100,4+($B9-1)*24+1+M$8*2)+$C9*INDEX(Curve!$G$1:$G$100,4+$B9*24+1+M$8*2)) -> 0.8749282 | N9: =$F9*MAX(0.001,(1-$C9)*INDEX(Curve!$G$1:$G$100,4+($B9-1)*24+1+N$8*2)+$C9*INDEX(Curve!$G$1:$G$100,4+$B9*24+1+N$8*2)) -> 0.7910919 | O9: =$F9*MAX(0.001,(1-$C9)*INDEX(Curve!$G$1:$G$100,4+($B9-1)*24+1+O$8*2)+$C9*INDEX(Curve!$G$1:$G$100,4+$B9*24+1+O$8*2)) -> 0.72873582 | P9: =$F9*MAX(0.001,(1-$C9)*INDEX(Curve!$G$1:$G$100,4+($B9-1)*24+1+P$8*2)+$C9*INDEX(Curve!$G$1:$G$100,4+$B9*24+1+P$8*2)) -> 0.67506288 | Q9: =$F9*MAX(0.001,(1-$C9)*INDEX(Curve!$G$1:$G$100,4+($B9-1)*24+1+Q$8*2)+$C9*INDEX(Curve!$G$1:$G$100,4+$B9*24+1+Q$8*2)) -> 0.6109714 | R9: =$F9*MAX(0.001,(1-$C9)*INDEX(Curve!$G$1:$G$100,4+($B9-1)*24+1+R$8*2)+$C9*INDEX(Curve!$G$1:$G$100,4+$B9*24+1+R$8*2)) -> 0.55184299 | S9: =$F9*MAX(0.001,(1-$C9)*INDEX(Curve!$G$1:$G$100,4+($B9-1)*24+1+S$8*2)+$C9*INDEX(Curve!$G$1:$G$100,4+$B9*24+1+S$8*2)) -> 0.50446721 | ... AD9: =$F9*MAX(0.001,(1-$C9)*INDEX(Curve!$G$1:$G$100,4+($B9-1)*24+1+AD$8*2)+$C9*INDEX(Curve!$G$1:$G$100,4+$B9*24+1+AD$8*2)) -> 0.13618481 | AE9: {=SUMPRODUCT(MAX(ISNUMBER(L9:AC9)*ISNUMBER(M9:AD9)*(L9:AC9>=$B$5)*(M9:AD9<$B$5)*(COLUMN(L9:AC9)-COLUMN(L9)+1)))} -> 16 | AF9: =IF(OR(AE9="",AE9=0),"",INDEX(L$8:AD$8,AE9)) -> 8 | AG9: =IF(AF9="","",INDEX(L$8:AD$8,AE9+1)) -> 8.5 | AH9: =IF(AF9="","",INDEX(L9:AD9,AE9)) -> 0.26049333 | AI9: =IF(AF9="","",INDEX(L9:AD9,AE9+1)) -> 0.23829847 | AJ9: =IFERROR(MATCH($B$6,L$8:AD$8,1),"") -> 16
A10: 600 | B10: =IFERROR(MIN(MATCH(A10,Parametri!$A$17:$A$19,1),2),1) -> 1 | C10: =(A10-INDEX(Parametri!$A$17:$A$19,B10))/(INDEX(Parametri!$A$17:$A$19,B10+1)-INDEX(Parametri!$A$17:$A$19,B10)) -> 0.2 | D10: =(1-C10)*INDEX(Riepilogo!$C$5:$C$7,B10)+C10*INDEX(Riepilogo!$C$5:$C$7,B10+1) -> 0.51178318 | E10: =A10/1000*Parametri!$B$4*D10 -> 0.012282796 | F10: =$B$4/3600/E10 -> 3.3922785 | G10: =$B$5/F10 -> 0.073696779 | H10: =(1-C10)*INDEX(Riepilogo!$F$5:$F$7,B10)+C10*INDEX(Riepilogo!$F$5:$F$7,B10+1) -> 0.13 | I10: =IF(AF10="",IF(ISNUMBER(L10),IF(L10<$B$5,"< 0,5","n.d."),"n.d."),EXP(LN(AF10)+(LN($B$5)-LN(AH10))*(LN(AG10)-LN(AF10))/(LN(AI10)-LN(AH10)))) -> 7.5528814 | J10: =IF(AJ10="","",IFERROR(EXP(LN(INDEX(L10:AD10,AJ10))+(LN($B$6)-LN(INDEX(L$8:AD$8,AJ10)))*(LN(INDEX(L10:AD10,AJ10+1))-LN(INDEX(L10:AD10,AJ10)))/(LN(INDEX(L$8:AD$8,AJ10+1))-LN(INDEX(L$8:AD$8,AJ10)))),"")) -> 0.22505993 | K10: =IF(OR(A10<MIN(Parametri!$A$17:$A$19),A10>MAX(Parametri!$A$17:$A$19)),"L fuori 500–1500 mm: estrapolazione",IF(OR($B$4<MAX(INDEX(Riepilogo!$H$5:$H$7,B10),INDEX(Riepilogo!$H$5:$H$7,B10+1))*0.99,$B$4>MIN(INDEX(Riepilogo!$I$5:$I$7,B10),INDEX(Riepilogo!$I$5:$I$7,B10+1))*1.01),"Q fuori dal campo simulato (estrapolazione)",IF(NOT(ISNUMBER(I10)),"vₜ non raggiunta / < 0,5 m",IF(G10>H10,"vₜ nel plateau/transizione: L poco significativo",IF(I10>Parametri!$B$7,"Oltre x max: troncato dal pavimento","OK"))))) -> OK | L10: =$F10*MAX(0.001,(1-$C10)*INDEX(Curve!$G$1:$G$100,4+($B10-1)*24+1+L$8*2)+$C10*INDEX(Curve!$G$1:$G$100,4+$B10*24+1+L$8*2)) -> 0.76705492 | M10: =$F10*MAX(0.001,(1-$C10)*INDEX(Curve!$G$1:$G$100,4+($B10-1)*24+1+M$8*2)+$C10*INDEX(Curve!$G$1:$G$100,4+$B10*24+1+M$8*2)) -> 0.72401674 | N10: =$F10*MAX(0.001,(1-$C10)*INDEX(Curve!$G$1:$G$100,4+($B10-1)*24+1+N$8*2)+$C10*INDEX(Curve!$G$1:$G$100,4+$B10*24+1+N$8*2)) -> 0.66903717 | O10: =$F10*MAX(0.001,(1-$C10)*INDEX(Curve!$G$1:$G$100,4+($B10-1)*24+1+O$8*2)+$C10*INDEX(Curve!$G$1:$G$100,4+$B10*24+1+O$8*2)) -> 0.62576815 | P10: =$F10*MAX(0.001,(1-$C10)*INDEX(Curve!$G$1:$G$100,4+($B10-1)*24+1+P$8*2)+$C10*INDEX(Curve!$G$1:$G$100,4+$B10*24+1+P$8*2)) -> 0.58568124 | Q10: =$F10*MAX(0.001,(1-$C10)*INDEX(Curve!$G$1:$G$100,4+($B10-1)*24+1+Q$8*2)+$C10*INDEX(Curve!$G$1:$G$100,4+$B10*24+1+Q$8*2)) -> 0.537081 | R10: =$F10*MAX(0.001,(1-$C10)*INDEX(Curve!$G$1:$G$100,4+($B10-1)*24+1+R$8*2)+$C10*INDEX(Curve!$G$1:$G$100,4+$B10*24+1+R$8*2)) -> 0.48886595 | S10: =$F10*MAX(0.001,(1-$C10)*INDEX(Curve!$G$1:$G$100,4+($B10-1)*24+1+S$8*2)+$C10*INDEX(Curve!$G$1:$G$100,4+$B10*24+1+S$8*2)) -> 0.44877823 | ... AD10: =$F10*MAX(0.001,(1-$C10)*INDEX(Curve!$G$1:$G$100,4+($B10-1)*24+1+AD$8*2)+$C10*INDEX(Curve!$G$1:$G$100,4+$B10*24+1+AD$8*2)) -> 0.12077505 | AE10: {=SUMPRODUCT(MAX(ISNUMBER(L10:AC10)*ISNUMBER(M10:AD10)*(L10:AC10>=$B$5)*(M10:AD10<$B$5)*(COLUMN(L10:AC10)-COLUMN(L10)+1)))} -> 15 | AF10: =IF(OR(AE10="",AE10=0),"",INDEX(L$8:AD$8,AE10)) -> 7.5 | AG10: =IF(AF10="","",INDEX(L$8:AD$8,AE10+1)) -> 8 | AH10: =IF(AF10="","",INDEX(L10:AD10,AE10)) -> 0.25202988 | AI10: =IF(AF10="","",INDEX(L10:AD10,AE10+1)) -> 0.23398725 | AJ10: =IFERROR(MATCH($B$6,L$8:AD$8,1),"") -> 16
A11: 700 | B11: =IFERROR(MIN(MATCH(A11,Parametri!$A$17:$A$19,1),2),1) -> 1 | C11: =(A11-INDEX(Parametri!$A$17:$A$19,B11))/(INDEX(Parametri!$A$17:$A$19,B11+1)-INDEX(Parametri!$A$17:$A$19,B11)) -> 0.4 | D11: =(1-C11)*INDEX(Riepilogo!$C$5:$C$7,B11)+C11*INDEX(Riepilogo!$C$5:$C$7,B11+1) -> 0.51673521 | E11: =A11/1000*Parametri!$B$4*D11 -> 0.014468586 | F11: =$B$4/3600/E11 -> 2.8798023 | G11: =$B$5/F11 -> 0.086811514 | H11: =(1-C11)*INDEX(Riepilogo!$F$5:$F$7,B11)+C11*INDEX(Riepilogo!$F$5:$F$7,B11+1) -> 0.135 | I11: =IF(AF11="",IF(ISNUMBER(L11),IF(L11<$B$5,"< 0,5","n.d."),"n.d."),EXP(LN(AF11)+(LN($B$5)-LN(AH11))*(LN(AG11)-LN(AF11))/(LN(AI11)-LN(AH11)))) -> 6.9508357 | J11: =IF(AJ11="","",IFERROR(EXP(LN(INDEX(L11:AD11,AJ11))+(LN($B$6)-LN(INDEX(L$8:AD$8,AJ11)))*(LN(INDEX(L11:AD11,AJ11+1))-LN(INDEX(L11:AD11,AJ11)))/(LN(INDEX(L$8:AD$8,AJ11+1))-LN(INDEX(L$8:AD$8,AJ11)))),"")) -> 0.20674869 | K11: =IF(OR(A11<MIN(Parametri!$A$17:$A$19),A11>MAX(Parametri!$A$17:$A$19)),"L fuori 500–1500 mm: estrapolazione",IF(OR($B$4<MAX(INDEX(Riepilogo!$H$5:$H$7,B11),INDEX(Riepilogo!$H$5:$H$7,B11+1))*0.99,$B$4>MIN(INDEX(Riepilogo!$I$5:$I$7,B11),INDEX(Riepilogo!$I$5:$I$7,B11+1))*1.01),"Q fuori dal campo simulato (estrapolazione)",IF(NOT(ISNUMBER(I11)),"vₜ non raggiunta / < 0,5 m",IF(G11>H11,"vₜ nel plateau/transizione: L poco significativo",IF(I11>Parametri!$B$7,"Oltre x max: troncato dal pavimento","OK"))))) -> OK | L11: =$F11*MAX(0.001,(1-$C11)*INDEX(Curve!$G$1:$G$100,4+($B11-1)*24+1+L$8*2)+$C11*INDEX(Curve!$G$1:$G$100,4+$B11*24+1+L$8*2)) -> 0.64648717 | M11: =$F11*MAX(0.001,(1-$C11)*INDEX(Curve!$G$1:$G$100,4+($B11-1)*24+1+M$8*2)+$C11*INDEX(Curve!$G$1:$G$100,4+$B11*24+1+M$8*2)) -> 0.61630646 | N11: =$F11*MAX(0.001,(1-$C11)*INDEX(Curve!$G$1:$G$100,4+($B11-1)*24+1+N$8*2)+$C11*INDEX(Curve!$G$1:$G$100,4+$B11*24+1+N$8*2)) -> 0.58169432 | O11: =$F11*MAX(0.001,(1-$C11)*INDEX(Curve!$G$1:$G$100,4+($B11-1)*24+1+O$8*2)+$C11*INDEX(Curve!$G$1:$G$100,4+$B11*24+1+O$8*2)) -> 0.55191607 | P11: =$F11*MAX(0.001,(1-$C11)*INDEX(Curve!$G$1:$G$100,4+($B11-1)*24+1+P$8*2)+$C11*INDEX(Curve!$G$1:$G$100,4+$B11*24+1+P$8*2)) -> 0.52145724 | Q11: =$F11*MAX(0.001,(1-$C11)*INDEX(Curve!$G$1:$G$100,4+($B11-1)*24+1+Q$8*2)+$C11*INDEX(Curve!$G$1:$G$100,4+$B11*24+1+Q$8*2)) -> 0.48384316 | R11: =$F11*MAX(0.001,(1-$C11)*INDEX(Curve!$G$1:$G$100,4+($B11-1)*24+1+R$8*2)+$C11*INDEX(Curve!$G$1:$G$100,4+$B11*24+1+R$8*2)) -> 0.44340597 | S11: =$F11*MAX(0.001,(1-$C11)*INDEX(Curve!$G$1:$G$100,4+($B11-1)*24+1+S$8*2)+$C11*INDEX(Curve!$G$1:$G$100,4+$B11*24+1+S$8*2)) -> 0.40853399 | ... AD11: =$F11*MAX(0.001,(1-$C11)*INDEX(Curve!$G$1:$G$100,4+($B11-1)*24+1+AD$8*2)+$C11*INDEX(Curve!$G$1:$G$100,4+$B11*24+1+AD$8*2)) -> 0.10964836 | AE11: {=SUMPRODUCT(MAX(ISNUMBER(L11:AC11)*ISNUMBER(M11:AD11)*(L11:AC11>=$B$5)*(M11:AD11<$B$5)*(COLUMN(L11:AC11)-COLUMN(L11)+1)))} -> 13 | AF11: =IF(OR(AE11="",AE11=0),"",INDEX(L$8:AD$8,AE11)) -> 6.5 | AG11: =IF(AF11="","",INDEX(L$8:AD$8,AE11+1)) -> 7 | AH11: =IF(AF11="","",INDEX(L11:AD11,AE11)) -> 0.26703343 | AI11: =IF(AF11="","",INDEX(L11:AD11,AE11+1)) -> 0.24827406 | AJ11: =IFERROR(MATCH($B$6,L$8:AD$8,1),"") -> 16
A12: 800 | B12: =IFERROR(MIN(MATCH(A12,Parametri!$A$17:$A$19,1),2),1) -> 1 | C12: =(A12-INDEX(Parametri!$A$17:$A$19,B12))/(INDEX(Parametri!$A$17:$A$19,B12+1)-INDEX(Parametri!$A$17:$A$19,B12)) -> 0.6 | D12: =(1-C12)*INDEX(Riepilogo!$C$5:$C$7,B12)+C12*INDEX(Riepilogo!$C$5:$C$7,B12+1) -> 0.52168723 | E12: =A12/1000*Parametri!$B$4*D12 -> 0.016693991 | F12: =$B$4/3600/E12 -> 2.495908 | G12: =$B$5/F12 -> 0.10016395 | H12: =(1-C12)*INDEX(Riepilogo!$F$5:$F$7,B12)+C12*INDEX(Riepilogo!$F$5:$F$7,B12+1) -> 0.14 | I12: =IF(AF12="",IF(ISNUMBER(L12),IF(L12<$B$5,"< 0,5","n.d."),"n.d."),EXP(LN(AF12)+(LN($B$5)-LN(AH12))*(LN(AG12)-LN(AF12))/(LN(AI12)-LN(AH12)))) -> 6.4916899 | J12: =IF(AJ12="","",IFERROR(EXP(LN(INDEX(L12:AD12,AJ12))+(LN($B$6)-LN(INDEX(L$8:AD$8,AJ12)))*(LN(INDEX(L12:AD12,AJ12+1))-LN(INDEX(L12:AD12,AJ12)))/(LN(INDEX(L$8:AD$8,AJ12+1))-LN(INDEX(L$8:AD$8,AJ12)))),"")) -> 0.19278524 | K12: =IF(OR(A12<MIN(Parametri!$A$17:$A$19),A12>MAX(Parametri!$A$17:$A$19)),"L fuori 500–1500 mm: estrapolazione",IF(OR($B$4<MAX(INDEX(Riepilogo!$H$5:$H$7,B12),INDEX(Riepilogo!$H$5:$H$7,B12+1))*0.99,$B$4>MIN(INDEX(Riepilogo!$I$5:$I$7,B12),INDEX(Riepilogo!$I$5:$I$7,B12+1))*1.01),"Q fuori dal campo simulato (estrapolazione)",IF(NOT(ISNUMBER(I12)),"vₜ non raggiunta / < 0,5 m",IF(G12>H12,"vₜ nel plateau/transizione: L poco significativo",IF(I12>Parametri!$B$7,"Oltre x max: troncato dal pavimento","OK"))))) -> OK | L12: =$F12*MAX(0.001,(1-$C12)*INDEX(Curve!$G$1:$G$100,4+($B12-1)*24+1+L$8*2)+$C12*INDEX(Curve!$G$1:$G$100,4+$B12*24+1+L$8*2)) -> 0.55624389 | M12: =$F12*MAX(0.001,(1-$C12)*INDEX(Curve!$G$1:$G$100,4+($B12-1)*24+1+M$8*2)+$C12*INDEX(Curve!$G$1:$G$100,4+$B12*24+1+M$8*2)) -> 0.53559484 | N12: =$F12*MAX(0.001,(1-$C12)*INDEX(Curve!$G$1:$G$100,4+($B12-1)*24+1+N$8*2)+$C12*INDEX(Curve!$G$1:$G$100,4+$B12*24+1+N$8*2)) -> 0.51605041 | O12: =$F12*MAX(0.001,(1-$C12)*INDEX(Curve!$G$1:$G$100,4+($B12-1)*24+1+O$8*2)+$C12*INDEX(Curve!$G$1:$G$100,4+$B12*24+1+O$8*2)) -> 0.49626882 | P12: =$F12*MAX(0.001,(1-$C12)*INDEX(Curve!$G$1:$G$100,4+($B12-1)*24+1+P$8*2)+$C12*INDEX(Curve!$G$1:$G$100,4+$B12*24+1+P$8*2)) -> 0.47296623 | Q12: =$F12*MAX(0.001,(1-$C12)*INDEX(Curve!$G$1:$G$100,4+($B12-1)*24+1+Q$8*2)+$C12*INDEX(Curve!$G$1:$G$100,4+$B12*24+1+Q$8*2)) -> 0.4435246 | R12: =$F12*MAX(0.001,(1-$C12)*INDEX(Curve!$G$1:$G$100,4+($B12-1)*24+1+R$8*2)+$C12*INDEX(Curve!$G$1:$G$100,4+$B12*24+1+R$8*2)) -> 0.40890604 | S12: =$F12*MAX(0.001,(1-$C12)*INDEX(Curve!$G$1:$G$100,4+($B12-1)*24+1+S$8*2)+$C12*INDEX(Curve!$G$1:$G$100,4+$B12*24+1+S$8*2)) -> 0.37795435 | ... AD12: =$F12*MAX(0.001,(1-$C12)*INDEX(Curve!$G$1:$G$100,4+($B12-1)*24+1+AD$8*2)+$C12*INDEX(Curve!$G$1:$G$100,4+$B12*24+1+AD$8*2)) -> 0.10120157 | AE12: {=SUMPRODUCT(MAX(ISNUMBER(L12:AC12)*ISNUMBER(M12:AD12)*(L12:AC12>=$B$5)*(M12:AD12<$B$5)*(COLUMN(L12:AC12)-COLUMN(L12)+1)))} -> 12 | AF12: =IF(OR(AE12="",AE12=0),"",INDEX(L$8:AD$8,AE12)) -> 6 | AG12: =IF(AF12="","",INDEX(L$8:AD$8,AE12+1)) -> 6.5 | AH12: =IF(AF12="","",INDEX(L12:AD12,AE12)) -> 0.26983837 | AI12: =IF(AF12="","",INDEX(L12:AD12,AE12+1)) -> 0.24969012 | AJ12: =IFERROR(MATCH($B$6,L$8:AD$8,1),"") -> 16
